Workbook

Sheet Shock Colcap
A1: Fecha datos | B1: Fecha Junta Directiva | C1: Fecha un día después | D1: Fecha dos días después | E1: Fecha tres días después | F1: Fecha cuatro días después | G1: Stock Fecha Junta | H1: Stock un día después | I1: Stock dos días después | J1: Stock tres días despues | K1: Stock cuatro días despues | L1: SHOCK STOCK
A2: 37257 | B2: 37274 | C2: =IF(B2="","",B2+1) -> 37275 | D2: =IF(B2="","",B2+2) -> 37276 | E2: =IF(B2="","",B2+3) -> 37277 | F2: =IF(B2="","",B2+4) -> 37278 | G2: =VLOOKUP(B2,COLCAP!B3:C4402,2,0) -> #N/A | H2: =VLOOKUP(C2,COLCAP!B3:C4402,2,0) -> #N/A | I2: =VLOOKUP(D2,COLCAP!B3:C4402,2,0) -> #N/A | J2: =VLOOKUP(E2,COLCAP!B3:C4402,2,0) -> #N/A | K2: =VLOOKUP(F2,COLCAP!B3:C4402,2,0) -> #N/A | L2: =IFERROR(LN(H2/G2),IFERROR(LN(I2/G2),IFERROR(LN(J2/G2),IFERROR(LN(K2/G2),""))))
A3: 37288 | B3: 37305 | C3: =IF(B3="","",B3+1) -> 37306 | D3: =IF(B3="","",B3+2) -> 37307 | E3: =IF(B3="","",B3+3) -> 37308 | F3: =IF(B3="","",B3+4) -> 37309 | G3: =VLOOKUP(B3,COLCAP!B4:C4403,2,0) -> #N/A | H3: =VLOOKUP(C3,COLCAP!B4:C4403,2,0) -> #N/A | I3: =VLOOKUP(D3,COLCAP!B4:C4403,2,0) -> #N/A | J3: =VLOOKUP(E3,COLCAP!B4:C4403,2,0) -> #N/A | K3: =VLOOKUP(F3,COLCAP!B4:C4403,2,0) -> #N/A | L3: =IFERROR(LN(H3/G3),IFERROR(LN(I3/G3),IFERROR(LN(J3/G3),IFERROR(LN(K3/G3),""))))
A4: 37316 | C4: =IF(B4="","",B4+1) | D4: =IF(B4="","",B4+2) | E4: =IF(B4="","",B4+3) | F4: =IF(B4="","",B4+4) | G4: =VLOOKUP(B4,COLCAP!B5:C4404,2,0) -> #N/A | H4: =VLOOKUP(C4,COLCAP!B5:C4404,2,0) -> #N/A | I4: =VLOOKUP(D4,COLCAP!B5:C4404,2,0) -> #N/A | J4: =VLOOKUP(E4,COLCAP!B5:C4404,2,0) -> #N/A | K4: =VLOOKUP(F4,COLCAP!B5:C4404,2,0) -> #N/A | L4: =IFERROR(LN(H4/G4),IFERROR(LN(I4/G4),IFERROR(LN(J4/G4),IFERROR(LN(K4/G4),""))))
A5: 37347 | B5: 37358 | C5: =IF(B5="","",B5+1) -> 37359 | D5: =IF(B5="","",B5+2) -> 37360 | E5: =IF(B5="","",B5+3) -> 37361 | F5: =IF(B5="","",B5+4) -> 37362 | G5: =VLOOKUP(B5,COLCAP!B6:C4405,2,0) -> #N/A | H5: =VLOOKUP(C5,COLCAP!B6:C4405,2,0) -> #N/A | I5: =VLOOKUP(D5,COLCAP!B6:C4405,2,0) -> #N/A | J5: =VLOOKUP(E5,COLCAP!B6:C4405,2,0) -> #N/A | K5: =VLOOKUP(F5,COLCAP!B6:C4405,2,0) -> #N/A | L5: =IFERROR(LN(H5/G5),IFERROR(LN(I5/G5),IFERROR(LN(J5/G5),IFERROR(LN(K5/G5),""))))
A6: 37377 | B6: 37393 | C6: =IF(B6="","",B6+1) -> 37394 | D6: =IF(B6="","",B6+2) -> 37395 | E6: =IF(B6="","",B6+3) -> 37396 | F6: =IF(B6="","",B6+4) -> 37397 | G6: =VLOOKUP(B6,COLCAP!B7:C4406,2,0) -> #N/A | H6: =VLOOKUP(C6,COLCAP!B7:C4406,2,0) -> #N/A | I6: =VLOOKUP(D6,COLCAP!B7:C4406,2,0) -> #N/A | J6: =VLOOKUP(E6,COLCAP!B7:C4406,2,0) -> #N/A | K6: =VLOOKUP(F6,COLCAP!B7:C4406,2,0) -> #N/A | L6: =IFERROR(LN(H6/G6),IFERROR(LN(I6/G6),IFERROR(LN(J6/G6),IFERROR(LN(K6/G6),""))))
A7: 37408 | C7: =IF(B7="","",B7+1) | D7: =IF(B7="","",B7+2) | E7: =IF(B7="","",B7+3) | F7: =IF(B7="","",B7+4) | G7: =VLOOKUP(B7,COLCAP!B8:C4407,2,0) -> #N/A | H7: =VLOOKUP(C7,COLCAP!B8:C4407,2,0) -> #N/A | I7: =VLOOKUP(D7,COLCAP!B8:C4407,2,0) -> #N/A | J7: =VLOOKUP(E7,COLCAP!B8:C4407,2,0) -> #N/A | K7: =VLOOKUP(F7,COLCAP!B8:C4407,2,0) -> #N/A | L7: =IFERROR(LN(H7/G7),IFERROR(LN(I7/G7),IFERROR(LN(J7/G7),IFERROR(LN(K7/G7),""))))
A8: 37438 | B8: 37456 | C8: =IF(B8="","",B8+1) -> 37457 | D8: =IF(B8="","",B8+2) -> 37458 | E8: =IF(B8="","",B8+3) -> 37459 | F8: =IF(B8="","",B8+4) -> 37460 | G8: =VLOOKUP(B8,COLCAP!B9:C4408,2,0) -> #N/A | H8: =VLOOKUP(C8,COLCAP!B9:C4408,2,0) -> #N/A | I8: =VLOOKUP(D8,COLCAP!B9:C4408,2,0) -> #N/A | J8: =VLOOKUP(E8,COLCAP!B9:C4408,2,0) -> #N/A | K8: =VLOOKUP(F8,COLCAP!B9:C4408,2,0) -> #N/A | L8: =IFERROR(LN(H8/G8),IFERROR(LN(I8/G8),IFERROR(LN(J8/G8),IFERROR(LN(K8/G8),""))))
A9: 37469 | B9: 37484 | C9: =IF(B9="","",B9+1) -> 37485 | D9: =IF(B9="","",B9+2) -> 37486 | E9: =IF(B9="","",B9+3) -> 37487 | F9: =IF(B9="","",B9+4) -> 37488 | G9: =VLOOKUP(B9,COLCAP!B10:C4409,2,0) -> #N/A | H9: =VLOOKUP(C9,COLCAP!B10:C4409,2,0) -> #N/A | I9: =VLOOKUP(D9,COLCAP!B10:C4409,2,0) -> #N/A | J9: =VLOOKUP(E9,COLCAP!B10:C4409,2,0) -> #N/A | K9: =VLOOKUP(F9,COLCAP!B10:C4409,2,0) -> #N/A | L9: =IFERROR(LN(H9/G9),IFERROR(LN(I9/G9),IFERROR(LN(J9/G9),IFERROR(LN(K9/G9),""))))
A10: 37500 | B10: 37512 | C10: =IF(B10="","",B10+1) -> 37513 | D10: =IF(B10="","",B10+2) -> 37514 | E10: =IF(B10="","",B10+3) -> 37515 | F10: =IF(B10="","",B10+4) -> 37516 | G10: =VLOOKUP(B10,COLCAP!B11:C4410,2,0) -> #N/A | H10: =VLOOKUP(C10,COLCAP!B11:C4410,2,0) -> #N/A | I10: =VLOOKUP(D10,COLCAP!B11:C4410,2,0) -> #N/A | J10: =VLOOKUP(E10,COLCAP!B11:C4410,2,0) -> #N/A | K10: =VLOOKUP(F10,COLCAP!B11:C4410,2,0) -> #N/A | L10: =IFERROR(LN(H10/G10),IFERROR(LN(I10/G10),IFERROR(LN(J10/G10),IFERROR(LN(K10/G10),""))))
A11: 37530 | B11: 37547 | C11: =IF(B11="","",B11+1) -> 37548 | D11: =IF(B11="","",B11+2) -> 37549 | E11: =IF(B11="","",B11+3) -> 37550 | F11: =IF(B11="","",B11+4) -> 37551 | G11: =VLOOKUP(B11,COLCAP!B12:C4411,2,0) -> #N/A | H11: =VLOOKUP(C11,COLCAP!B12:C4411,2,0) -> #N/A | I11: =VLOOKUP(D11,COLCAP!B12:C4411,2,0) -> #N/A | J11: =VLOOKUP(E11,COLCAP!B12:C4411,2,0) -> #N/A | K11: =VLOOKUP(F11,COLCAP!B12:C4411,2,0) -> #N/A | L11: =IFERROR(LN(H11/G11),IFERROR(LN(I11/G11),IFERROR(LN(J11/G11),IFERROR(LN(K11/G11),""))))
A12: 37561 | B12: 37581 | C12: =IF(B12="","",B12+1) -> 37582 | D12: =IF(B12="","",B12+2) -> 37583 | E12: =IF(B12="","",B12+3) -> 37584 | F12: =IF(B12="","",B12+4) -> 37585 | G12: =VLOOKUP(B12,COLCAP!B13:C4412,2,0) -> #N/A | H12: =VLOOKUP(C12,COLCAP!B13:C4412,2,0) -> #N/A | I12: =VLOOKUP(D12,COLCAP!B13:C4412,2,0) -> #N/A | J12: =VLOOKUP(E12,COLCAP!B13:C4412,2,0) -> #N/A | K12: =VLOOKUP(F12,COLCAP!B13:C4412,2,0) -> #N/A | L12: =IFERROR(LN(H12/G12),IFERROR(LN(I12/G12),IFERROR(LN(J12/G12),IFERROR(LN(K12/G12),""))))
A13: 37591 | B13: 37613 | C13: =IF(B13="","",B13+1) -> 37614 | D13: =IF(B13="","",B13+2) -> 37615 | E13: =IF(B13="","",B13+3) -> 37616 | F13: =IF(B13="","",B13+4) -> 37617 | G13: =VLOOKUP(B13,COLCAP!B14:C4413,2,0) -> #N/A | H13: =VLOOKUP(C13,COLCAP!B14:C4413,2,0) -> #N/A | I13: =VLOOKUP(D13,COLCAP!B14:C4413,2,0) -> #N/A | J13: =VLOOKUP(E13,COLCAP!B14:C4413,2,0) -> #N/A | K13: =VLOOKUP(F13,COLCAP!B14:C4413,2,0) -> #N/A | L13: =IFERROR(LN(H13/G13),IFERROR(LN(I13/G13),IFERROR(LN(J13/G13),IFERROR(LN(K13/G13),""))))
A14: 37622 | C14: =IF(B14="","",B14+1) | D14: =IF(B14="","",B14+2) | E14: =IF(B14="","",B14+3) | F14: =IF(B14="","",B14+4) | G14: =VLOOKUP(B14,COLCAP!B15:C4414,2,0) -> #N/A | H14: =VLOOKUP(C14,COLCAP!B15:C4414,2,0) -> #N/A | I14: =VLOOKUP(D14,COLCAP!B15:C4414,2,0) -> #N/A | J14: =VLOOKUP(E14,COLCAP!B15:C4414,2,0) -> #N/A | K14: =VLOOKUP(F14,COLCAP!B15:C4414,2,0) -> #N/A | L14: =IFERROR(LN(H14/G14),IFERROR(LN(I14/G14),IFERROR(LN(J14/G14),IFERROR(LN(K14/G14),""))))
A15: 37653 | B15: 37666 | C15: =IF(B15="","",B15+1) -> 37667 | D15: =IF(B15="","",B15+2) -> 37668 | E15: =IF(B15="","",B15+3) -> 37669 | F15: =IF(B15="","",B15+4) -> 37670 | G15: =VLOOKUP(B15,COLCAP!B16:C4415,2,0) -> #N/A | H15: =VLOOKUP(C15,COLCAP!B16:C4415,2,0) -> #N/A | I15: =VLOOKUP(D15,COLCAP!B16:C4415,2,0) -> #N/A | J15: =VLOOKUP(E15,COLCAP!B16:C4415,2,0) -> #N/A | K15: =VLOOKUP(F15,COLCAP!B16:C4415,2,0) -> #N/A | L15: =IFERROR(LN(H15/G15),IFERROR(LN(I15/G15),IFERROR(LN(J15/G15),IFERROR(LN(K15/G15),""))))
A16: 37681 | B16: 37694 | C16: =IF(B16="","",B16+1) -> 37695 | D16: =IF(B16="","",B16+2) -> 37696 | E16: =IF(B16="","",B16+3) -> 37697 | F16: =IF(B16="","",B16+4) -> 37698 | G16: =VLOOKUP(B16,COLCAP!B17:C4416,2,0) -> #N/A | H16: =VLOOKUP(C16,COLCAP!B17:C4416,2,0) -> #N/A | I16: =VLOOKUP(D16,COLCAP!B17:C4416,2,0) -> #N/A | J16: =VLOOKUP(E16,COLCAP!B17:C4416,2,0) -> #N/A | K16: =VLOOKUP(F16,COLCAP!B17:C4416,2,0) -> #N/A | L16: =IFERROR(LN(H16/G16),IFERROR(LN(I16/G16),IFERROR(LN(J16/G16),IFERROR(LN(K16/G16),""))))
A17: 37712 | B17: 37739 | C17: =IF(B17="","",B17+1) -> 37740 | D17: =IF(B17="","",B17+2) -> 37741 | E17: =IF(B17="","",B17+3) -> 37742 | F17: =IF(B17="","",B17+4) -> 37743 | G17: =VLOOKUP(B17,COLCAP!B18:C4417,2,0) -> #N/A | H17: =VLOOKUP(C17,COLCAP!B18:C4417,2,0) -> #N/A | I17: =VLOOKUP(D17,COLCAP!B18:C4417,2,0) -> #N/A | J17: =VLOOKUP(E17,COLCAP!B18:C4417,2,0) -> #N/A | K17: =VLOOKUP(F17,COLCAP!B18:C4417,2,0) -> #N/A | L17: =IFERROR(LN(H17/G17),IFERROR(LN(I17/G17),IFERROR(LN(J17/G17),IFERROR(LN(K17/G17),""))))
A18: 37742 | B18: 37757 | C18: =IF(B18="","",B18+1) -> 37758 | D18: =IF(B18="","",B18+2) -> 37759 | E18: =IF(B18="","",B18+3) -> 37760 | F18: =IF(B18="","",B18+4) -> 37761 | G18: =VLOOKUP(B18,COLCAP!B19:C4418,2,0) -> #N/A | H18: =VLOOKUP(C18,COLCAP!B19:C4418,2,0) -> #N/A | I18: =VLOOKUP(D18,COLCAP!B19:C4418,2,0) -> #N/A | J18: =VLOOKUP(E18,COLCAP!B19:C4418,2,0) -> #N/A | K18: =VLOOKUP(F18,COLCAP!B19:C4418,2,0) -> #N/A | L18: =IFERROR(LN(H18/G18),IFERROR(LN(I18/G18),IFERROR(LN(J18/G18),IFERROR(LN(K18/G18),""))))
A19: 37773 | B19: 37792 | C19: =IF(B19="","",B19+1) -> 37793 | D19: =IF(B19="","",B19+2) -> 37794 | E19: =IF(B19="","",B19+3) -> 37795 | F19: =IF(B19="","",B19+4) -> 37796 | G19: =VLOOKUP(B19,COLCAP!B20:C4419,2,0) -> #N/A | H19: =VLOOKUP(C19,COLCAP!B20:C4419,2,0) -> #N/A | I19: =VLOOKUP(D19,COLCAP!B20:C4419,2,0) -> #N/A | J19: =VLOOKUP(E19,COLCAP!B20:C4419,2,0) -> #N/A | K19: =VLOOKUP(F19,COLCAP!B20:C4419,2,0) -> #N/A | L19: =IFERROR(LN(H19/G19),IFERROR(LN(I19/G19),IFERROR(LN(J19/G19),IFERROR(LN(K19/G19),""))))
A20: 37803 | B20: 37827 | C20: =IF(B20="","",B20+1) -> 37828 | D20: =IF(B20="","",B20+2) -> 37829 | E20: =IF(B20="","",B20+3) -> 37830 | F20: =IF(B20="","",B20+4) -> 37831 | G20: =VLOOKUP(B20,COLCAP!B21:C4420,2,0) -> #N/A | H20: =VLOOKUP(C20,COLCAP!B21:C4420,2,0) -> #N/A | I20: =VLOOKUP(D20,COLCAP!B21:C4420,2,0) -> #N/A | J20: =VLOOKUP(E20,COLCAP!B21:C4420,2,0) -> #N/A | K20: =VLOOKUP(F20,COLCAP!B21:C4420,2,0) -> #N/A | L20: =IFERROR(LN(H20/G20),IFERROR(LN(I20/G20),IFERROR(LN(J20/G20),IFERROR(LN(K20/G20),""))))
A21: 37834 | B21: 37848 | C21: =IF(B21="","",B21+1) -> 37849 | D21: =IF(B21="","",B21+2) -> 37850 | E21: =IF(B21="","",B21+3) -> 37851 | F21: =IF(B21="","",B21+4) -> 37852 | G21: =VLOOKUP(B21,COLCAP!B22:C4421,2,0) -> #N/A | H21: =VLOOKUP(C21,COLCAP!B22:C4421,2,0) -> #N/A | I21: =VLOOKUP(D21,COLCAP!B22:C4421,2,0) -> #N/A | J21: =VLOOKUP(E21,COLCAP!B22:C4421,2,0) -> #N/A | K21: =VLOOKUP(F21,COLCAP!B22:C4421,2,0) -> #N/A | L21: =IFERROR(LN(H21/G21),IFERROR(LN(I21/G21),IFERROR(LN(J21/G21),IFERROR(LN(K21/G21),""))))
A22: 37865 | B22: 37876 | C22: =IF(B22="","",B22+1) -> 37877 | D22: =IF(B22="","",B22+2) -> 37878 | E22: =IF(B22="","",B22+3) -> 37879 | F22: =IF(B22="","",B22+4) -> 37880 | G22: =VLOOKUP(B22,COLCAP!B23:C4422,2,0) -> #N/A | H22: =VLOOKUP(C22,COLCAP!B23:C4422,2,0) -> #N/A | I22: =VLOOKUP(D22,COLCAP!B23:C4422,2,0) -> #N/A | J22: =VLOOKUP(E22,COLCAP!B23:C4422,2,0) -> #N/A | K22: =VLOOKUP(F22,COLCAP!B23:C4422,2,0) -> #N/A | L22: =IFERROR(LN(H22/G22),IFERROR(LN(I22/G22),IFERROR(LN(J22/G22),IFERROR(LN(K22/G22),""))))
A23: 37895 | B23: 37918 | C23: =IF(B23="","",B23+1) -> 37919 | D23: =IF(B23="","",B23+2) -> 37920 | E23: =IF(B23="","",B23+3) -> 37921 | F23: =IF(B23="","",B23+4) -> 37922 | G23: =VLOOKUP(B23,COLCAP!B24:C4423,2,0) -> #N/A | H23: =VLOOKUP(C23,COLCAP!B24:C4423,2,0) -> #N/A | I23: =VLOOKUP(D23,COLCAP!B24:C4423,2,0) -> #N/A | J23: =VLOOKUP(E23,COLCAP!B24:C4423,2,0) -> #N/A | K23: =VLOOKUP(F23,COLCAP!B24:C4423,2,0) -> #N/A | L23: =IFERROR(LN(H23/G23),IFERROR(LN(I23/G23),IFERROR(LN(J23/G23),IFERROR(LN(K23/G23),""))))
A24: 37926 | B24: 37939 | C24: =IF(B24="","",B24+1) -> 37940 | D24: =IF(B24="","",B24+2) -> 37941 | E24: =IF(B24="","",B24+3) -> 37942 | F24: =IF(B24="","",B24+4) -> 37943 | G24: =VLOOKUP(B24,COLCAP!B25:C4424,2,0) -> #N/A | H24: =VLOOKUP(C24,COLCAP!B25:C4424,2,0) -> #N/A | I24: =VLOOKUP(D24,COLCAP!B25:C4424,2,0) -> #N/A | J24: =VLOOKUP(E24,COLCAP!B25:C4424,2,0) -> #N/A | K24: =VLOOKUP(F24,COLCAP!B25:C4424,2,0) -> #N/A | L24: =IFERROR(LN(H24/G24),IFERROR(LN(I24/G24),IFERROR(LN(J24/G24),IFERROR(LN(K24/G24),""))))
A25: 37956 | B25: 37974 | C25: =IF(B25="","",B25+1) -> 37975 | D25: =IF(B25="","",B25+2) -> 37976 | E25: =IF(B25="","",B25+3) -> 37977 | F25: =IF(B25="","",B25+4) -> 37978 | G25: =VLOOKUP(B25,COLCAP!B26:C4425,2,0) -> #N/A | H25: =VLOOKUP(C25,COLCAP!B26:C4425,2,0) -> #N/A | I25: =VLOOKUP(D25,COLCAP!B26:C4425,2,0) -> #N/A | J25: =VLOOKUP(E25,COLCAP!B26:C4425,2,0) -> #N/A | K25: =VLOOKUP(F25,COLCAP!B26:C4425,2,0) -> #N/A | L25: =IFERROR(LN(H25/G25),IFERROR(LN(I25/G25),IFERROR(LN(J25/G25),IFERROR(LN(K25/G25),""))))
A26: 37987 | B26: 38009 | C26: =IF(B26="","",B26+1) -> 38010 | D26: =IF(B26="","",B26+2) -> 38011 | E26: =IF(B26="","",B26+3) -> 38012 | F26: =IF(B26="","",B26+4) -> 38013 | G26: =VLOOKUP(B26,COLCAP!B27:C4426,2,0) -> #N/A | H26: =VLOOKUP(C26,COLCAP!B27:C4426,2,0) -> #N/A | I26: =VLOOKUP(D26,COLCAP!B27:C4426,2,0) -> #N/A | J26: =VLOOKUP(E26,COLCAP!B27:C4426,2,0) -> #N/A | K26: =VLOOKUP(F26,COLCAP!B27:C4426,2,0) -> #N/A | L26: =IFERROR(LN(H26/G26),IFERROR(LN(I26/G26),IFERROR(LN(J26/G26),IFERROR(LN(K26/G26),""))))
... A143: 41548 | B143: 41572 | C143: =IF(B143="","",B143+1) -> 41573 | D143: =IF(B143="","",B143+2) -> 41574 | E143: =IF(B143="","",B143+3) -> 41575 | F143: =IF(B143="","",B143+4) -> 41576 | G143: =VLOOKUP(B143,COLCAP!B144:C4543,2,0) -> 1773.84 | H143: =VLOOKUP(C143,COLCAP!B144:C4543,2,0) -> #N/A | I143: =VLOOKUP(D143,COLCAP!B144:C4543,2,0) -> #N/A | J143: =VLOOKUP(E143,COLCAP!B144:C4543,2,0) -> 1763.16 | K143: =VLOOKUP(F143,COLCAP!B144:C4543,2,0) -> 1763.01 | L143: =IFERROR(LN(H143/G143),IFERROR(LN(I143/G143),IFERROR(LN(J143/G143),IFERROR(LN(K143/G143),"")))) -> -0.0060390345
A144: 41579 | C144: =IF(B144="","",B144+1) | D144: =IF(B144="","",B144+2) | E144: =IF(B144="","",B144+3) | F144: =IF(B144="","",B144+4) | G144: =VLOOKUP(B144,COLCAP!B145:C4544,2,0) -> #N/A | H144: =VLOOKUP(C144,COLCAP!B145:C4544,2,0) -> #N/A | I144: =VLOOKUP(D144,COLCAP!B145:C4544,2,0) -> #N/A | J144: =VLOOKUP(E144,COLCAP!B145:C4544,2,0) -> #N/A | K144: =VLOOKUP(F144,COLCAP!B145:C4544,2,0) -> #N/A | L144: =IFERROR(LN(H144/G144),IFERROR(LN(I144/G144),IFERROR(LN(J144/G144),IFERROR(LN(K144/G144),""))))
A145: 41609 | B145: 41628 | C145: =IF(B145="","",B145+1) -> 41629 | D145: =IF(B145="","",B145+2) -> 41630 | E145: =IF(B145="","",B145+3) -> 41631 | F145: =IF(B145="","",B145+4) -> 41632 | G145: =VLOOKUP(B145,COLCAP!B146:C4545,2,0) -> 1630.43 | H145: =VLOOKUP(C145,COLCAP!B146:C4545,2,0) -> #N/A | I145: =VLOOKUP(D145,COLCAP!B146:C4545,2,0) -> #N/A | J145: =VLOOKUP(E145,COLCAP!B146:C4545,2,0) -> 1602.6 | K145: =VLOOKUP(F145,COLCAP!B146:C4545,2,0) -> 1613.81 | L145: =IFERROR(LN(H145/G145),IFERROR(LN(I145/G145),IFERROR(LN(J145/G145),IFERROR(LN(K145/G145),"")))) -> -0.017216473
A146: 41640 | B146: 41670 | C146: =IF(B146="","",B146+1) -> 41671 | D146: =IF(B146="","",B146+2) -> 41672 | E146: =IF(B146="","",B146+3) -> 41673 | F146: =IF(B146="","",B146+4) -> 41674 | G146: =VLOOKUP(B146,COLCAP!B147:C4546,2,0) -> 1460.04 | H146: =VLOOKUP(C146,COLCAP!B147:C4546,2,0) -> #N/A | I146: =VLOOKUP(D146,COLCAP!B147:C4546,2,0) -> #N/A | J146: =VLOOKUP(E146,COLCAP!B147:C4546,2,0) -> 1448.56 | K146: =VLOOKUP(F146,COLCAP!B147:C4546,2,0) -> 1451.76 | L146: =IFERROR(LN(H146/G146),IFERROR(LN(I146/G146),IFERROR(LN(J146/G146),IFERROR(LN(K146/G146),"")))) -> -0.0078938731
A147: 41671 | B147: 41698 | C147: =IF(B147="","",B147+1) -> 41699 | D147: =IF(B147="","",B147+2) -> 41700 | E147: =IF(B147="","",B147+3) -> 41701 | F147: =IF(B147="","",B147+4) -> 41702 | G147: =VLOOKUP(B147,COLCAP!B148:C4547,2,0) -> 1520.74 | H147: =VLOOKUP(C147,COLCAP!B148:C4547,2,0) -> #N/A | I147: =VLOOKUP(D147,COLCAP!B148:C4547,2,0) -> #N/A | J147: =VLOOKUP(E147,COLCAP!B148:C4547,2,0) -> 1504.11 | K147: =VLOOKUP(F147,COLCAP!B148:C4547,2,0) -> 1539.33 | L147: =IFERROR(LN(H147/G147),IFERROR(LN(I147/G147),IFERROR(LN(J147/G147),IFERROR(LN(K147/G147),"")))) -> -0.010995697
A148: 41699 | B148: 41719 | C148: =IF(B148="","",B148+1) -> 41720 | D148: =IF(B148="","",B148+2) -> 41721 | E148: =IF(B148="","",B148+3) -> 41722 | F148: =IF(B148="","",B148+4) -> 41723 | G148: =VLOOKUP(B148,COLCAP!B149:C4548,2,0) -> 1607.95 | H148: =VLOOKUP(C148,COLCAP!B149:C4548,2,0) -> #N/A | I148: =VLOOKUP(D148,COLCAP!B149:C4548,2,0) -> #N/A | J148: =VLOOKUP(E148,COLCAP!B149:C4548,2,0) -> #N/A | K148: =VLOOKUP(F148,COLCAP!B149:C4548,2,0) -> 1639.02 | L148: =IFERROR(LN(H148/G148),IFERROR(LN(I148/G148),IFERROR(LN(J148/G148),IFERROR(LN(K148/G148),"")))) -> 0.019138427
A149: 41730 | B149: 41754 | C149: =IF(B149="","",B149+1) -> 41755 | D149: =IF(B149="","",B149+2) -> 41756 | E149: =IF(B149="","",B149+3) -> 41757 | F149: =IF(B149="","",B149+4) -> 41758 | G149: =VLOOKUP(B149,COLCAP!B150:C4549,2,0) -> 1641.46 | H149: =VLOOKUP(C149,COLCAP!B150:C4549,2,0) -> #N/A | I149: =VLOOKUP(D149,COLCAP!B150:C4549,2,0) -> #N/A | J149: =VLOOKUP(E149,COLCAP!B150:C4549,2,0) -> 1642.1 | K149: =VLOOKUP(F149,COLCAP!B150:C4549,2,0) -> 1653.62 | L149: =IFERROR(LN(H149/G149),IFERROR(LN(I149/G149),IFERROR(LN(J149/G149),IFERROR(LN(K149/G149),"")))) -> 0.00038982081
A150: 41760 | B150: 41789 | C150: =IF(B150="","",B150+1) -> 41790 | D150: =IF(B150="","",B150+2) -> 41791 | E150: =IF(B150="","",B150+3) -> 41792 | F150: =IF(B150="","",B150+4) -> 41793 | G150: =VLOOKUP(B150,COLCAP!B151:C4550,2,0) -> 1659.05 | H150: =VLOOKUP(C150,COLCAP!B151:C4550,2,0) -> #N/A | I150: =VLOOKUP(D150,COLCAP!B151:C4550,2,0) -> #N/A | J150: =VLOOKUP(E150,COLCAP!B151:C4550,2,0) -> #N/A | K150: =VLOOKUP(F150,COLCAP!B151:C4550,2,0) -> 1678.97 | L150: =IFERROR(LN(H150/G150),IFERROR(LN(I150/G150),IFERROR(LN(J150/G150),IFERROR(LN(K150/G150),"")))) -> 0.011935361
A151: 41791 | B151: 41810 | C151: =IF(B151="","",B151+1) -> 41811 | D151: =IF(B151="","",B151+2) -> 41812 | E151: =IF(B151="","",B151+3) -> 41813 | F151: =IF(B151="","",B151+4) -> 41814 | G151: =VLOOKUP(B151,COLCAP!B152:C4551,2,0) -> 1725.13 | H151: =VLOOKUP(C151,COLCAP!B152:C4551,2,0) -> #N/A | I151: =VLOOKUP(D151,COLCAP!B152:C4551,2,0) -> #N/A | J151: =VLOOKUP(E151,COLCAP!B152:C4551,2,0) -> #N/A | K151: =VLOOKUP(F151,COLCAP!B152:C4551,2,0) -> 1723.7 | L151: =IFERROR(LN(H151/G151),IFERROR(LN(I151/G151),IFERROR(LN(J151/G151),IFERROR(LN(K151/G151),"")))) -> -0.00082926678
A152: 41821 | B152: 41851 | C152: =IF(B152="","",B152+1) -> 41852 | D152: =IF(B152="","",B152+2) -> 41853 | E152: =IF(B152="","",B152+3) -> 41854 | F152: =IF(B152="","",B152+4) -> 41855 | G152: =VLOOKUP(B152,COLCAP!B153:C4552,2,0) -> 1694.59 | H152: =VLOOKUP(C152,COLCAP!B153:C4552,2,0) -> 1693.06 | I152: =VLOOKUP(D152,COLCAP!B153:C4552,2,0) -> #N/A | J152: =VLOOKUP(E152,COLCAP!B153:C4552,2,0) -> #N/A | K152: =VLOOKUP(F152,COLCAP!B153:C4552,2,0) -> 1712.97 | L152: =IFERROR(LN(H152/G152),IFERROR(LN(I152/G152),IFERROR(LN(J152/G152),IFERROR(LN(K152/G152),"")))) -> -0.0009032811
A153: 41852 | B153: 41880 | C153: =IF(B153="","",B153+1) -> 41881 | D153: =IF(B153="","",B153+2) -> 41882 | E153: =IF(B153="","",B153+3) -> 41883 | F153: =IF(B153="","",B153+4) -> 41884 | G153: =VLOOKUP(B153,COLCAP!B154:C4553,2,0) -> 1771.18 | H153: =VLOOKUP(C153,COLCAP!B154:C4553,2,0) -> #N/A | I153: =VLOOKUP(D153,COLCAP!B154:C4553,2,0) -> #N/A | J153: =VLOOKUP(E153,COLCAP!B154:C4553,2,0) -> 1776.76 | K153: =VLOOKUP(F153,COLCAP!B154:C4553,2,0) -> 1777.53 | L153: =IFERROR(LN(H153/G153),IFERROR(LN(I153/G153),IFERROR(LN(J153/G153),IFERROR(LN(K153/G153),"")))) -> 0.0031454898
A154: 41883 | B154: 41908 | C154: =IF(B154="","",B154+1) -> 41909 | D154: =IF(B154="","",B154+2) -> 41910 | E154: =IF(B154="","",B154+3) -> 41911 | F154: =IF(B154="","",B154+4) -> 41912 | G154: =VLOOKUP(B154,COLCAP!B155:C4554,2,0) -> 1678 | H154: =VLOOKUP(C154,COLCAP!B155:C4554,2,0) -> #N/A | I154: =VLOOKUP(D154,COLCAP!B155:C4554,2,0) -> #N/A | J154: =VLOOKUP(E154,COLCAP!B155:C4554,2,0) -> 1678.48 | K154: =VLOOKUP(F154,COLCAP!B155:C4554,2,0) -> 1665.7 | L154: =IFERROR(LN(H154/G154),IFERROR(LN(I154/G154),IFERROR(LN(J154/G154),IFERROR(LN(K154/G154),"")))) -> 0.00028601392
A155: 41913 | B155: 41942 | C155: =IF(B155="","",B155+1) -> 41943 | D155: =IF(B155="","",B155+2) -> 41944 | E155: =IF(B155="","",B155+3) -> 41945 | F155: =IF(B155="","",B155+4) -> 41946 | G155: =VLOOKUP(B155,COLCAP!B156:C4555,2,0) -> 1626.22 | H155: =VLOOKUP(C155,COLCAP!B156:C4555,2,0) -> 1634.88 | I155: =VLOOKUP(D155,COLCAP!B156:C4555,2,0) -> #N/A | J155: =VLOOKUP(E155,COLCAP!B156:C4555,2,0) -> #N/A | K155: =VLOOKUP(F155,COLCAP!B156:C4555,2,0) -> #N/A | L155: =IFERROR(LN(H155/G155),IFERROR(LN(I155/G155),IFERROR(LN(J155/G155),IFERROR(LN(K155/G155),"")))) -> 0.0053111038
A156: 41944 | B156: 41971 | C156: =IF(B156="","",B156+1) -> 41972 | D156: =IF(B156="","",B156+2) -> 41973 | E156: =IF(B156="","",B156+3) -> 41974 | F156: =IF(B156="","",B156+4) -> 41975 | G156: =VLOOKUP(B156,COLCAP!B157:C4556,2,0) -> 1525.68 | H156: =VLOOKUP(C156,COLCAP!B157:C4556,2,0) -> #N/A | I156: =VLOOKUP(D156,COLCAP!B157:C4556,2,0) -> #N/A | J156: =VLOOKUP(E156,COLCAP!B157:C4556,2,0) -> 1510.06 | K156: =VLOOKUP(F156,COLCAP!B157:C4556,2,0) -> 1497.59 | L156: =IFERROR(LN(H156/G156),IFERROR(LN(I156/G156),IFERROR(LN(J156/G156),IFERROR(LN(K156/G156),"")))) -> -0.010290827
...

Sheet Shocks BEI
A1: Fecha datos | B1: Fecha Junta Directiva | C1: Fecha un día después | D1: Fecha dos días después | E1: Fecha tres días después | F1: Fecha cuatro días después | G1: Stock Fecha Junta | H1: Stock un día después | I1: Stock dos días después | J1: Stock tres días despues | K1: Stock cuatro días despues | L1: SHOCK BEI
A2: 37257 | B2: 37274 | C2: =IF(B2="","",B2+1) -> 37275 | D2: =IF(B2="","",B2+2) -> 37276 | E2: =IF(B2="","",B2+3) -> 37277 | F2: =IF(B2="","",B2+4) -> 37278 | G2: =VLOOKUP(B2,BEI!B3:C5627,2,0) -> #N/A | H2: =VLOOKUP(C2,BEI!B3:C5627,2,0) -> #N/A | I2: =VLOOKUP(D2,BEI!B3:C5627,2,0) -> #N/A | J2: =VLOOKUP(E2,BEI!B3:C5627,2,0) -> #N/A | K2: =VLOOKUP(F2,BEI!B3:C5627,2,0) -> #N/A | L2: =IFERROR((H2-G2),IFERROR((I2-G2),IFERROR((J2-G2),IFERROR((K2-G2),""))))
A3: 37288 | B3: 37305 | C3: =IF(B3="","",B3+1) -> 37306 | D3: =IF(B3="","",B3+2) -> 37307 | E3: =IF(B3="","",B3+3) -> 37308 | F3: =IF(B3="","",B3+4) -> 37309 | G3: =VLOOKUP(B3,BEI!B4:C5628,2,0) -> #N/A | H3: =VLOOKUP(C3,BEI!B4:C5628,2,0) -> #N/A | I3: =VLOOKUP(D3,BEI!B4:C5628,2,0) -> #N/A | J3: =VLOOKUP(E3,BEI!B4:C5628,2,0) -> #N/A | K3: =VLOOKUP(F3,BEI!B4:C5628,2,0) -> #N/A | L3: =IFERROR((H3-G3),IFERROR((I3-G3),IFERROR((J3-G3),IFERROR((K3-G3),""))))
A4: 37316 | C4: =IF(B4="","",B4+1) | D4: =IF(B4="","",B4+2) | E4: =IF(B4="","",B4+3) | F4: =IF(B4="","",B4+4) | G4: =VLOOKUP(B4,BEI!B5:C5629,2,0) -> #N/A | H4: =VLOOKUP(C4,BEI!B5:C5629,2,0) -> #N/A | I4: =VLOOKUP(D4,BEI!B5:C5629,2,0) -> #N/A | J4: =VLOOKUP(E4,BEI!B5:C5629,2,0) -> #N/A | K4: =VLOOKUP(F4,BEI!B5:C5629,2,0) -> #N/A | L4: =IFERROR((H4-G4),IFERROR((I4-G4),IFERROR((J4-G4),IFERROR((K4-G4),""))))
A5: 37347 | B5: 37358 | C5: =IF(B5="","",B5+1) -> 37359 | D5: =IF(B5="","",B5+2) -> 37360 | E5: =IF(B5="","",B5+3) -> 37361 | F5: =IF(B5="","",B5+4) -> 37362 | G5: =VLOOKUP(B5,BEI!B6:C5630,2,0) -> #N/A | H5: =VLOOKUP(C5,BEI!B6:C5630,2,0) -> #N/A | I5: =VLOOKUP(D5,BEI!B6:C5630,2,0) -> #N/A | J5: =VLOOKUP(E5,BEI!B6:C5630,2,0) -> #N/A | K5: =VLOOKUP(F5,BEI!B6:C5630,2,0) -> #N/A | L5: =IFERROR((H5-G5),IFERROR((I5-G5),IFERROR((J5-G5),IFERROR((K5-G5),""))))
A6: 37377 | B6: 37393 | C6: =IF(B6="","",B6+1) -> 37394 | D6: =IF(B6="","",B6+2) -> 37395 | E6: =IF(B6="","",B6+3) -> 37396 | F6: =IF(B6="","",B6+4) -> 37397 | G6: =VLOOKUP(B6,BEI!B7:C5631,2,0) -> #N/A | H6: =VLOOKUP(C6,BEI!B7:C5631,2,0) -> #N/A | I6: =VLOOKUP(D6,BEI!B7:C5631,2,0) -> #N/A | J6: =VLOOKUP(E6,BEI!B7:C5631,2,0) -> #N/A | K6: =VLOOKUP(F6,BEI!B7:C5631,2,0) -> #N/A | L6: =IFERROR((H6-G6),IFERROR((I6-G6),IFERROR((J6-G6),IFERROR((K6-G6),""))))
A7: 37408 | C7: =IF(B7="","",B7+1) | D7: =IF(B7="","",B7+2) | E7: =IF(B7="","",B7+3) | F7: =IF(B7="","",B7+4) | G7: =VLOOKUP(B7,BEI!B8:C5632,2,0) -> #N/A | H7: =VLOOKUP(C7,BEI!B8:C5632,2,0) -> #N/A | I7: =VLOOKUP(D7,BEI!B8:C5632,2,0) -> #N/A | J7: =VLOOKUP(E7,BEI!B8:C5632,2,0) -> #N/A | K7: =VLOOKUP(F7,BEI!B8:C5632,2,0) -> #N/A | L7: =IFERROR((H7-G7),IFERROR((I7-G7),IFERROR((J7-G7),IFERROR((K7-G7),""))))
A8: 37438 | B8: 37456 | C8: =IF(B8="","",B8+1) -> 37457 | D8: =IF(B8="","",B8+2) -> 37458 | E8: =IF(B8="","",B8+3) -> 37459 | F8: =IF(B8="","",B8+4) -> 37460 | G8: =VLOOKUP(B8,BEI!B9:C5633,2,0) -> #N/A | H8: =VLOOKUP(C8,BEI!B9:C5633,2,0) -> #N/A | I8: =VLOOKUP(D8,BEI!B9:C5633,2,0) -> #N/A | J8: =VLOOKUP(E8,BEI!B9:C5633,2,0) -> #N/A | K8: =VLOOKUP(F8,BEI!B9:C5633,2,0) -> #N/A | L8: =IFERROR((H8-G8),IFERROR((I8-G8),IFERROR((J8-G8),IFERROR((K8-G8),""))))
A9: 37469 | B9: 37484 | C9: =IF(B9="","",B9+1) -> 37485 | D9: =IF(B9="","",B9+2) -> 37486 | E9: =IF(B9="","",B9+3) -> 37487 | F9: =IF(B9="","",B9+4) -> 37488 | G9: =VLOOKUP(B9,BEI!B10:C5634,2,0) -> #N/A | H9: =VLOOKUP(C9,BEI!B10:C5634,2,0) -> #N/A | I9: =VLOOKUP(D9,BEI!B10:C5634,2,0) -> #N/A | J9: =VLOOKUP(E9,BEI!B10:C5634,2,0) -> #N/A | K9: =VLOOKUP(F9,BEI!B10:C5634,2,0) -> #N/A | L9: =IFERROR((H9-G9),IFERROR((I9-G9),IFERROR((J9-G9),IFERROR((K9-G9),""))))
A10: 37500 | B10: 37512 | C10: =IF(B10="","",B10+1) -> 37513 | D10: =IF(B10="","",B10+2) -> 37514 | E10: =IF(B10="","",B10+3) -> 37515 | F10: =IF(B10="","",B10+4) -> 37516 | G10: =VLOOKUP(B10,BEI!B11:C5635,2,0) -> #N/A | H10: =VLOOKUP(C10,BEI!B11:C5635,2,0) -> #N/A | I10: =VLOOKUP(D10,BEI!B11:C5635,2,0) -> #N/A | J10: =VLOOKUP(E10,BEI!B11:C5635,2,0) -> #N/A | K10: =VLOOKUP(F10,BEI!B11:C5635,2,0) -> #N/A | L10: =IFERROR((H10-G10),IFERROR((I10-G10),IFERROR((J10-G10),IFERROR((K10-G10),""))))
A11: 37530 | B11: 37547 | C11: =IF(B11="","",B11+1) -> 37548 | D11: =IF(B11="","",B11+2) -> 37549 | E11: =IF(B11="","",B11+3) -> 37550 | F11: =IF(B11="","",B11+4) -> 37551 | G11: =VLOOKUP(B11,BEI!B12:C5636,2,0) -> #N/A | H11: =VLOOKUP(C11,BEI!B12:C5636,2,0) -> #N/A | I11: =VLOOKUP(D11,BEI!B12:C5636,2,0) -> #N/A | J11: =VLOOKUP(E11,BEI!B12:C5636,2,0) -> #N/A | K11: =VLOOKUP(F11,BEI!B12:C5636,2,0) -> #N/A | L11: =IFERROR((H11-G11),IFERROR((I11-G11),IFERROR((J11-G11),IFERROR((K11-G11),""))))
A12: 37561 | B12: 37581 | C12: =IF(B12="","",B12+1) -> 37582 | D12: =IF(B12="","",B12+2) -> 37583 | E12: =IF(B12="","",B12+3) -> 37584 | F12: =IF(B12="","",B12+4) -> 37585 | G12: =VLOOKUP(B12,BEI!B13:C5637,2,0) -> #N/A | H12: =VLOOKUP(C12,BEI!B13:C5637,2,0) -> #N/A | I12: =VLOOKUP(D12,BEI!B13:C5637,2,0) -> #N/A | J12: =VLOOKUP(E12,BEI!B13:C5637,2,0) -> #N/A | K12: =VLOOKUP(F12,BEI!B13:C5637,2,0) -> #N/A | L12: =IFERROR((H12-G12),IFERROR((I12-G12),IFERROR((J12-G12),IFERROR((K12-G12),""))))
A13: 37591 | B13: 37613 | C13: =IF(B13="","",B13+1) -> 37614 | D13: =IF(B13="","",B13+2) -> 37615 | E13: =IF(B13="","",B13+3) -> 37616 | F13: =IF(B13="","",B13+4) -> 37617 | G13: =VLOOKUP(B13,BEI!B14:C5638,2,0) -> #N/A | H13: =VLOOKUP(C13,BEI!B14:C5638,2,0) -> #N/A | I13: =VLOOKUP(D13,BEI!B14:C5638,2,0) -> #N/A | J13: =VLOOKUP(E13,BEI!B14:C5638,2,0) -> #N/A | K13: =VLOOKUP(F13,BEI!B14:C5638,2,0) -> #N/A | L13: =IFERROR((H13-G13),IFERROR((I13-G13),IFERROR((J13-G13),IFERROR((K13-G13),""))))
A14: 37622 | C14: =IF(B14="","",B14+1) | D14: =IF(B14="","",B14+2) | E14: =IF(B14="","",B14+3) | F14: =IF(B14="","",B14+4) | G14: =VLOOKUP(B14,BEI!B15:C5639,2,0) -> #N/A | H14: =VLOOKUP(C14,BEI!B15:C5639,2,0) -> #N/A | I14: =VLOOKUP(D14,BEI!B15:C5639,2,0) -> #N/A | J14: =VLOOKUP(E14,BEI!B15:C5639,2,0) -> #N/A | K14: =VLOOKUP(F14,BEI!B15:C5639,2,0) -> #N/A | L14: =IFERROR((H14-G14),IFERROR((I14-G14),IFERROR((J14-G14),IFERROR((K14-G14),""))))
A15: 37653 | B15: 37666 | C15: =IF(B15="","",B15+1) -> 37667 | D15: =IF(B15="","",B15+2) -> 37668 | E15: =IF(B15="","",B15+3) -> 37669 | F15: =IF(B15="","",B15+4) -> 37670 | G15: =VLOOKUP(B15,BEI!B16:C5640,2,0) -> 8.02 | H15: =VLOOKUP(C15,BEI!B16:C5640,2,0) -> #N/A | I15: =VLOOKUP(D15,BEI!B16:C5640,2,0) -> #N/A | J15: =VLOOKUP(E15,BEI!B16:C5640,2,0) -> 7.78 | K15: =VLOOKUP(F15,BEI!B16:C5640,2,0) -> 7.76 | L15: =IFERROR((H15-G15),IFERROR((I15-G15),IFERROR((J15-G15),IFERROR((K15-G15),"")))) -> -0.24
A16: 37681 | B16: 37694 | C16: =IF(B16="","",B16+1) -> 37695 | D16: =IF(B16="","",B16+2) -> 37696 | E16: =IF(B16="","",B16+3) -> 37697 | F16: =IF(B16="","",B16+4) -> 37698 | G16: =VLOOKUP(B16,BEI!B17:C5641,2,0) -> 7.75 | H16: =VLOOKUP(C16,BEI!B17:C5641,2,0) -> #N/A | I16: =VLOOKUP(D16,BEI!B17:C5641,2,0) -> #N/A | J16: =VLOOKUP(E16,BEI!B17:C5641,2,0) -> 7.2 | K16: =VLOOKUP(F16,BEI!B17:C5641,2,0) -> 7.13 | L16: =IFERROR((H16-G16),IFERROR((I16-G16),IFERROR((J16-G16),IFERROR((K16-G16),"")))) -> -0.55
A17: 37712 | B17: 37739 | C17: =IF(B17="","",B17+1) -> 37740 | D17: =IF(B17="","",B17+2) -> 37741 | E17: =IF(B17="","",B17+3) -> 37742 | F17: =IF(B17="","",B17+4) -> 37743 | G17: =VLOOKUP(B17,BEI!B18:C5642,2,0) -> 6.02 | H17: =VLOOKUP(C17,BEI!B18:C5642,2,0) -> 6.18 | I17: =VLOOKUP(D17,BEI!B18:C5642,2,0) -> 6.17 | J17: =VLOOKUP(E17,BEI!B18:C5642,2,0) -> #N/A | K17: =VLOOKUP(F17,BEI!B18:C5642,2,0) -> 6.21 | L17: =IFERROR((H17-G17),IFERROR((I17-G17),IFERROR((J17-G17),IFERROR((K17-G17),"")))) -> 0.16
A18: 37742 | B18: 37757 | C18: =IF(B18="","",B18+1) -> 37758 | D18: =IF(B18="","",B18+2) -> 37759 | E18: =IF(B18="","",B18+3) -> 37760 | F18: =IF(B18="","",B18+4) -> 37761 | G18: =VLOOKUP(B18,BEI!B19:C5643,2,0) -> 7.03 | H18: =VLOOKUP(C18,BEI!B19:C5643,2,0) -> #N/A | I18: =VLOOKUP(D18,BEI!B19:C5643,2,0) -> #N/A | J18: =VLOOKUP(E18,BEI!B19:C5643,2,0) -> 6 | K18: =VLOOKUP(F18,BEI!B19:C5643,2,0) -> 6.37 | L18: =IFERROR((H18-G18),IFERROR((I18-G18),IFERROR((J18-G18),IFERROR((K18-G18),"")))) -> -1.03
A19: 37773 | B19: 37792 | C19: =IF(B19="","",B19+1) -> 37793 | D19: =IF(B19="","",B19+2) -> 37794 | E19: =IF(B19="","",B19+3) -> 37795 | F19: =IF(B19="","",B19+4) -> 37796 | G19: =VLOOKUP(B19,BEI!B20:C5644,2,0) -> 5.35 | H19: =VLOOKUP(C19,BEI!B20:C5644,2,0) -> #N/A | I19: =VLOOKUP(D19,BEI!B20:C5644,2,0) -> #N/A | J19: =VLOOKUP(E19,BEI!B20:C5644,2,0) -> #N/A | K19: =VLOOKUP(F19,BEI!B20:C5644,2,0) -> 5.67 | L19: =IFERROR((H19-G19),IFERROR((I19-G19),IFERROR((J19-G19),IFERROR((K19-G19),"")))) -> 0.32
A20: 37803 | B20: 37827 | C20: =IF(B20="","",B20+1) -> 37828 | D20: =IF(B20="","",B20+2) -> 37829 | E20: =IF(B20="","",B20+3) -> 37830 | F20: =IF(B20="","",B20+4) -> 37831 | G20: =VLOOKUP(B20,BEI!B21:C5645,2,0) -> 5.15 | H20: =VLOOKUP(C20,BEI!B21:C5645,2,0) -> #N/A | I20: =VLOOKUP(D20,BEI!B21:C5645,2,0) -> #N/A | J20: =VLOOKUP(E20,BEI!B21:C5645,2,0) -> 5.34 | K20: =VLOOKUP(F20,BEI!B21:C5645,2,0) -> 5.44 | L20: =IFERROR((H20-G20),IFERROR((I20-G20),IFERROR((J20-G20),IFERROR((K20-G20),"")))) -> 0.19
A21: 37834 | B21: 37848 | C21: =IF(B21="","",B21+1) -> 37849 | D21: =IF(B21="","",B21+2) -> 37850 | E21: =IF(B21="","",B21+3) -> 37851 | F21: =IF(B21="","",B21+4) -> 37852 | G21: =VLOOKUP(B21,BEI!B22:C5646,2,0) -> 5.08 | H21: =VLOOKUP(C21,BEI!B22:C5646,2,0) -> #N/A | I21: =VLOOKUP(D21,BEI!B22:C5646,2,0) -> #N/A | J21: =VLOOKUP(E21,BEI!B22:C5646,2,0) -> #N/A | K21: =VLOOKUP(F21,BEI!B22:C5646,2,0) -> 5.05 | L21: =IFERROR((H21-G21),IFERROR((I21-G21),IFERROR((J21-G21),IFERROR((K21-G21),"")))) -> -0.03
A22: 37865 | B22: 37876 | C22: =IF(B22="","",B22+1) -> 37877 | D22: =IF(B22="","",B22+2) -> 37878 | E22: =IF(B22="","",B22+3) -> 37879 | F22: =IF(B22="","",B22+4) -> 37880 | G22: =VLOOKUP(B22,BEI!B23:C5647,2,0) -> 5.82 | H22: =VLOOKUP(C22,BEI!B23:C5647,2,0) -> #N/A | I22: =VLOOKUP(D22,BEI!B23:C5647,2,0) -> #N/A | J22: =VLOOKUP(E22,BEI!B23:C5647,2,0) -> 5.79 | K22: =VLOOKUP(F22,BEI!B23:C5647,2,0) -> 5.95 | L22: =IFERROR((H22-G22),IFERROR((I22-G22),IFERROR((J22-G22),IFERROR((K22-G22),"")))) -> -0.03
A23: 37895 | B23: 37918 | C23: =IF(B23="","",B23+1) -> 37919 | D23: =IF(B23="","",B23+2) -> 37920 | E23: =IF(B23="","",B23+3) -> 37921 | F23: =IF(B23="","",B23+4) -> 37922 | G23: =VLOOKUP(B23,BEI!B24:C5648,2,0) -> 6.44 | H23: =VLOOKUP(C23,BEI!B24:C5648,2,0) -> #N/A | I23: =VLOOKUP(D23,BEI!B24:C5648,2,0) -> #N/A | J23: =VLOOKUP(E23,BEI!B24:C5648,2,0) -> 6.3 | K23: =VLOOKUP(F23,BEI!B24:C5648,2,0) -> 6.89 | L23: =IFERROR((H23-G23),IFERROR((I23-G23),IFERROR((J23-G23),IFERROR((K23-G23),"")))) -> -0.14
A24: 37926 | B24: 37939 | C24: =IF(B24="","",B24+1) -> 37940 | D24: =IF(B24="","",B24+2) -> 37941 | E24: =IF(B24="","",B24+3) -> 37942 | F24: =IF(B24="","",B24+4) -> 37943 | G24: =VLOOKUP(B24,BEI!B25:C5649,2,0) -> 6.21 | H24: =VLOOKUP(C24,BEI!B25:C5649,2,0) -> #N/A | I24: =VLOOKUP(D24,BEI!B25:C5649,2,0) -> #N/A | J24: =VLOOKUP(E24,BEI!B25:C5649,2,0) -> #N/A | K24: =VLOOKUP(F24,BEI!B25:C5649,2,0) -> 6.7 | L24: =IFERROR((H24-G24),IFERROR((I24-G24),IFERROR((J24-G24),IFERROR((K24-G24),"")))) -> 0.49
A25: 37956 | B25: 37974 | C25: =IF(B25="","",B25+1) -> 37975 | D25: =IF(B25="","",B25+2) -> 37976 | E25: =IF(B25="","",B25+3) -> 37977 | F25: =IF(B25="","",B25+4) -> 37978 | G25: =VLOOKUP(B25,BEI!B26:C5650,2,0) -> 6.67 | H25: =VLOOKUP(C25,BEI!B26:C5650,2,0) -> #N/A | I25: =VLOOKUP(D25,BEI!B26:C5650,2,0) -> #N/A | J25: =VLOOKUP(E25,BEI!B26:C5650,2,0) -> 6.85 | K25: =VLOOKUP(F25,BEI!B26:C5650,2,0) -> 5.91 | L25: =IFERROR((H25-G25),IFERROR((I25-G25),IFERROR((J25-G25),IFERROR((K25-G25),"")))) -> 0.18
A26: 37987 | B26: 38009 | C26: =IF(B26="","",B26+1) -> 38010 | D26: =IF(B26="","",B26+2) -> 38011 | E26: =IF(B26="","",B26+3) -> 38012 | F26: =IF(B26="","",B26+4) -> 38013 | G26: =VLOOKUP(B26,BEI!B27:C5651,2,0) -> 7.6 | H26: =VLOOKUP(C26,BEI!B27:C5651,2,0) -> #N/A | I26: =VLOOKUP(D26,BEI!B27:C5651,2,0) -> #N/A | J26: =VLOOKUP(E26,BEI!B27:C5651,2,0) -> 7.51 | K26: =VLOOKUP(F26,BEI!B27:C5651,2,0) -> 7.48 | L26: =IFERROR((H26-G26),IFERROR((I26-G26),IFERROR((J26-G26),IFERROR((K26-G26),"")))) -> -0.09
... A143: 41548 | B143: 41572 | C143: =IF(B143="","",B143+1) -> 41573 | D143: =IF(B143="","",B143+2) -> 41574 | E143: =IF(B143="","",B143+3) -> 41575 | F143: =IF(B143="","",B143+4) -> 41576 | G143: =VLOOKUP(B143,BEI!B144:C5768,2,0) -> 2.51 | H143: =VLOOKUP(C143,BEI!B144:C5768,2,0) -> #N/A | I143: =VLOOKUP(D143,BEI!B144:C5768,2,0) -> #N/A | J143: =VLOOKUP(E143,BEI!B144:C5768,2,0) -> 2.54 | K143: =VLOOKUP(F143,BEI!B144:C5768,2,0) -> 2.51 | L143: =IFERROR((H143-G143),IFERROR((I143-G143),IFERROR((J143-G143),IFERROR((K143-G143),"")))) -> 0.03
A144: 41579 | C144: =IF(B144="","",B144+1) | D144: =IF(B144="","",B144+2) | E144: =IF(B144="","",B144+3) | F144: =IF(B144="","",B144+4) | G144: =VLOOKUP(B144,BEI!B145:C5769,2,0) -> #N/A | H144: =VLOOKUP(C144,BEI!B145:C5769,2,0) -> #N/A | I144: =VLOOKUP(D144,BEI!B145:C5769,2,0) -> #N/A | J144: =VLOOKUP(E144,BEI!B145:C5769,2,0) -> #N/A | K144: =VLOOKUP(F144,BEI!B145:C5769,2,0) -> #N/A | L144: =IFERROR((H144-G144),IFERROR((I144-G144),IFERROR((J144-G144),IFERROR((K144-G144),""))))
A145: 41609 | B145: 41628 | C145: =IF(B145="","",B145+1) -> 41629 | D145: =IF(B145="","",B145+2) -> 41630 | E145: =IF(B145="","",B145+3) -> 41631 | F145: =IF(B145="","",B145+4) -> 41632 | G145: =VLOOKUP(B145,BEI!B146:C5770,2,0) -> 2.58 | H145: =VLOOKUP(C145,BEI!B146:C5770,2,0) -> #N/A | I145: =VLOOKUP(D145,BEI!B146:C5770,2,0) -> #N/A | J145: =VLOOKUP(E145,BEI!B146:C5770,2,0) -> 2.62 | K145: =VLOOKUP(F145,BEI!B146:C5770,2,0) -> 2.33 | L145: =IFERROR((H145-G145),IFERROR((I145-G145),IFERROR((J145-G145),IFERROR((K145-G145),"")))) -> 0.04
A146: 41640 | B146: 41670 | C146: =IF(B146="","",B146+1) -> 41671 | D146: =IF(B146="","",B146+2) -> 41672 | E146: =IF(B146="","",B146+3) -> 41673 | F146: =IF(B146="","",B146+4) -> 41674 | G146: =VLOOKUP(B146,BEI!B147:C5771,2,0) -> 2.8 | H146: =VLOOKUP(C146,BEI!B147:C5771,2,0) -> #N/A | I146: =VLOOKUP(D146,BEI!B147:C5771,2,0) -> #N/A | J146: =VLOOKUP(E146,BEI!B147:C5771,2,0) -> 2.87 | K146: =VLOOKUP(F146,BEI!B147:C5771,2,0) -> 2.77 | L146: =IFERROR((H146-G146),IFERROR((I146-G146),IFERROR((J146-G146),IFERROR((K146-G146),"")))) -> 0.07
A147: 41671 | B147: 41698 | C147: =IF(B147="","",B147+1) -> 41699 | D147: =IF(B147="","",B147+2) -> 41700 | E147: =IF(B147="","",B147+3) -> 41701 | F147: =IF(B147="","",B147+4) -> 41702 | G147: =VLOOKUP(B147,BEI!B148:C5772,2,0) -> 2.96 | H147: =VLOOKUP(C147,BEI!B148:C5772,2,0) -> #N/A | I147: =VLOOKUP(D147,BEI!B148:C5772,2,0) -> #N/A | J147: =VLOOKUP(E147,BEI!B148:C5772,2,0) -> 2.94 | K147: =VLOOKUP(F147,BEI!B148:C5772,2,0) -> 2.92 | L147: =IFERROR((H147-G147),IFERROR((I147-G147),IFERROR((J147-G147),IFERROR((K147-G147),"")))) -> -0.02
A148: 41699 | B148: 41719 | C148: =IF(B148="","",B148+1) -> 41720 | D148: =IF(B148="","",B148+2) -> 41721 | E148: =IF(B148="","",B148+3) -> 41722 | F148: =IF(B148="","",B148+4) -> 41723 | G148: =VLOOKUP(B148,BEI!B149:C5773,2,0) -> 2.57 | H148: =VLOOKUP(C148,BEI!B149:C5773,2,0) -> #N/A | I148: =VLOOKUP(D148,BEI!B149:C5773,2,0) -> #N/A | J148: =VLOOKUP(E148,BEI!B149:C5773,2,0) -> #N/A | K148: =VLOOKUP(F148,BEI!B149:C5773,2,0) -> 2.57 | L148: =IFERROR((H148-G148),IFERROR((I148-G148),IFERROR((J148-G148),IFERROR((K148-G148),"")))) -> 4.4408921e-16
A149: 41730 | B149: 41754 | C149: =IF(B149="","",B149+1) -> 41755 | D149: =IF(B149="","",B149+2) -> 41756 | E149: =IF(B149="","",B149+3) -> 41757 | F149: =IF(B149="","",B149+4) -> 41758 | G149: =VLOOKUP(B149,BEI!B150:C5774,2,0) -> 2.62 | H149: =VLOOKUP(C149,BEI!B150:C5774,2,0) -> #N/A | I149: =VLOOKUP(D149,BEI!B150:C5774,2,0) -> #N/A | J149: =VLOOKUP(E149,BEI!B150:C5774,2,0) -> 2.57 | K149: =VLOOKUP(F149,BEI!B150:C5774,2,0) -> 2.48 | L149: =IFERROR((H149-G149),IFERROR((I149-G149),IFERROR((J149-G149),IFERROR((K149-G149),"")))) -> -0.05
A150: 41760 | B150: 41789 | C150: =IF(B150="","",B150+1) -> 41790 | D150: =IF(B150="","",B150+2) -> 41791 | E150: =IF(B150="","",B150+3) -> 41792 | F150: =IF(B150="","",B150+4) -> 41793 | G150: =VLOOKUP(B150,BEI!B151:C5775,2,0) -> 2.5 | H150: =VLOOKUP(C150,BEI!B151:C5775,2,0) -> #N/A | I150: =VLOOKUP(D150,BEI!B151:C5775,2,0) -> #N/A | J150: =VLOOKUP(E150,BEI!B151:C5775,2,0) -> #N/A | K150: =VLOOKUP(F150,BEI!B151:C5775,2,0) -> 2.68 | L150: =IFERROR((H150-G150),IFERROR((I150-G150),IFERROR((J150-G150),IFERROR((K150-G150),"")))) -> 0.18
A151: 41791 | B151: 41810 | C151: =IF(B151="","",B151+1) -> 41811 | D151: =IF(B151="","",B151+2) -> 41812 | E151: =IF(B151="","",B151+3) -> 41813 | F151: =IF(B151="","",B151+4) -> 41814 | G151: =VLOOKUP(B151,BEI!B152:C5776,2,0) -> 2.92 | H151: =VLOOKUP(C151,BEI!B152:C5776,2,0) -> #N/A | I151: =VLOOKUP(D151,BEI!B152:C5776,2,0) -> #N/A | J151: =VLOOKUP(E151,BEI!B152:C5776,2,0) -> #N/A | K151: =VLOOKUP(F151,BEI!B152:C5776,2,0) -> 2.84 | L151: =IFERROR((H151-G151),IFERROR((I151-G151),IFERROR((J151-G151),IFERROR((K151-G151),"")))) -> -0.08
A152: 41821 | B152: 41851 | C152: =IF(B152="","",B152+1) -> 41852 | D152: =IF(B152="","",B152+2) -> 41853 | E152: =IF(B152="","",B152+3) -> 41854 | F152: =IF(B152="","",B152+4) -> 41855 | G152: =VLOOKUP(B152,BEI!B153:C5777,2,0) -> 3.51 | H152: =VLOOKUP(C152,BEI!B153:C5777,2,0) -> 3.68 | I152: =VLOOKUP(D152,BEI!B153:C5777,2,0) -> #N/A | J152: =VLOOKUP(E152,BEI!B153:C5777,2,0) -> #N/A | K152: =VLOOKUP(F152,BEI!B153:C5777,2,0) -> 2.89 | L152: =IFERROR((H152-G152),IFERROR((I152-G152),IFERROR((J152-G152),IFERROR((K152-G152),"")))) -> 0.17
A153: 41852 | B153: 41880 | C153: =IF(B153="","",B153+1) -> 41881 | D153: =IF(B153="","",B153+2) -> 41882 | E153: =IF(B153="","",B153+3) -> 41883 | F153: =IF(B153="","",B153+4) -> 41884 | G153: =VLOOKUP(B153,BEI!B154:C5778,2,0) -> 2.73 | H153: =VLOOKUP(C153,BEI!B154:C5778,2,0) -> #N/A | I153: =VLOOKUP(D153,BEI!B154:C5778,2,0) -> #N/A | J153: =VLOOKUP(E153,BEI!B154:C5778,2,0) -> 2.68 | K153: =VLOOKUP(F153,BEI!B154:C5778,2,0) -> 2.64 | L153: =IFERROR((H153-G153),IFERROR((I153-G153),IFERROR((J153-G153),IFERROR((K153-G153),"")))) -> -0.05
A154: 41883 | B154: 41908 | C154: =IF(B154="","",B154+1) -> 41909 | D154: =IF(B154="","",B154+2) -> 41910 | E154: =IF(B154="","",B154+3) -> 41911 | F154: =IF(B154="","",B154+4) -> 41912 | G154: =VLOOKUP(B154,BEI!B155:C5779,2,0) -> 2.71 | H154: =VLOOKUP(C154,BEI!B155:C5779,2,0) -> #N/A | I154: =VLOOKUP(D154,BEI!B155:C5779,2,0) -> #N/A | J154: =VLOOKUP(E154,BEI!B155:C5779,2,0) -> 2.8 | K154: =VLOOKUP(F154,BEI!B155:C5779,2,0) -> 2.73 | L154: =IFERROR((H154-G154),IFERROR((I154-G154),IFERROR((J154-G154),IFERROR((K154-G154),"")))) -> 0.09
A155: 41913 | B155: 41942 | C155: =IF(B155="","",B155+1) -> 41943 | D155: =IF(B155="","",B155+2) -> 41944 | E155: =IF(B155="","",B155+3) -> 41945 | F155: =IF(B155="","",B155+4) -> 41946 | G155: =VLOOKUP(B155,BEI!B156:C5780,2,0) -> 3.01 | H155: =VLOOKUP(C155,BEI!B156:C5780,2,0) -> 2.68 | I155: =VLOOKUP(D155,BEI!B156:C5780,2,0) -> #N/A | J155: =VLOOKUP(E155,BEI!B156:C5780,2,0) -> #N/A | K155: =VLOOKUP(F155,BEI!B156:C5780,2,0) -> #N/A | L155: =IFERROR((H155-G155),IFERROR((I155-G155),IFERROR((J155-G155),IFERROR((K155-G155),"")))) -> -0.33
A156: 41944 | B156: 41971 | C156: =IF(B156="","",B156+1) -> 41972 | D156: =IF(B156="","",B156+2) -> 41973 | E156: =IF(B156="","",B156+3) -> 41974 | F156: =IF(B156="","",B156+4) -> 41975 | G156: =VLOOKUP(B156,BEI!B157:C5781,2,0) -> 3.64 | H156: =VLOOKUP(C156,BEI!B157:C5781,2,0) -> #N/A | I156: =VLOOKUP(D156,BEI!B157:C5781,2,0) -> #N/A | J156: =VLOOKUP(E156,BEI!B157:C5781,2,0) -> 3.62 | K156: =VLOOKUP(F156,BEI!B157:C5781,2,0) -> 3.76 | L156: =IFERROR((H156-G156),IFERROR((I156-G156),IFERROR((J156-G156),IFERROR((K156-G156),"")))) -> -0.02
...

Sheet Shocks WTI
A1: Fecha datos | B1: Fecha Junta Directiva | C1: Fecha un día después | D1: Fecha dos días después | E1: Fecha tres días después | F1: Fecha cuatro días después | G1: Stock Fecha Junta | H1: Stock un día después | I1: Stock dos días después | J1: Stock tres días despues | K1: Stock cuatro días despues | L1: SHOCK WTI | M1: Shock colcap | N1: Shock BEI
A2: 37257 | B2: 37274 | C2: =IF(B2="","",B2+1) -> 37275 | D2: =IF(B2="","",B2+2) -> 37276 | E2: =IF(B2="","",B2+3) -> 37277 | F2: =IF(B2="","",B2+4) -> 37278 | G2: =VLOOKUP(B2,WTI!A2:B10524,2,0) -> 18.02 | H2: =VLOOKUP(C2,WTI!A2:B10524,2,0) -> #N/A | I2: =VLOOKUP(D2,WTI!A2:B10524,2,0) -> #N/A | J2: =VLOOKUP(E2,WTI!A2:B10524,2,0) -> 18.02 | K2: =VLOOKUP(F2,WTI!A2:B10524,2,0) -> 18.36 | L2: =IFERROR(LN(H2/G2),IFERROR(LN(I2/G2),IFERROR(LN(J2/G2),IFERROR(LN(K2/G2),"")))) -> 0
A3: 37288 | B3: 37305 | C3: =IF(B3="","",B3+1) -> 37306 | D3: =IF(B3="","",B3+2) -> 37307 | E3: =IF(B3="","",B3+3) -> 37308 | F3: =IF(B3="","",B3+4) -> 37309 | G3: =VLOOKUP(B3,WTI!A3:B10525,2,0) -> 21.47 | H3: =VLOOKUP(C3,WTI!A3:B10525,2,0) -> 20.77 | I3: =VLOOKUP(D3,WTI!A3:B10525,2,0) -> 20.31 | J3: =VLOOKUP(E3,WTI!A3:B10525,2,0) -> 20.81 | K3: =VLOOKUP(F3,WTI!A3:B10525,2,0) -> 20.92 | L3: =IFERROR(LN(H3/G3),IFERROR(LN(I3/G3),IFERROR(LN(J3/G3),IFERROR(LN(K3/G3),"")))) -> -0.033146974
A4: 37316 | C4: =IF(B4="","",B4+1) | D4: =IF(B4="","",B4+2) | E4: =IF(B4="","",B4+3) | F4: =IF(B4="","",B4+4) | G4: =VLOOKUP(B4,WTI!A4:B10526,2,0) -> #N/A | H4: =VLOOKUP(C4,WTI!A4:B10526,2,0) -> #N/A | I4: =VLOOKUP(D4,WTI!A4:B10526,2,0) -> #N/A | J4: =VLOOKUP(E4,WTI!A4:B10526,2,0) -> #N/A | K4: =VLOOKUP(F4,WTI!A4:B10526,2,0) -> #N/A | L4: =IFERROR(LN(H4/G4),IFERROR(LN(I4/G4),IFERROR(LN(J4/G4),IFERROR(LN(K4/G4),""))))
A5: 37347 | B5: 37358 | C5: =IF(B5="","",B5+1) -> 37359 | D5: =IF(B5="","",B5+2) -> 37360 | E5: =IF(B5="","",B5+3) -> 37361 | F5: =IF(B5="","",B5+4) -> 37362 | G5: =VLOOKUP(B5,WTI!A5:B10527,2,0) -> 23.51 | H5: =VLOOKUP(C5,WTI!A5:B10527,2,0) -> #N/A | I5: =VLOOKUP(D5,WTI!A5:B10527,2,0) -> #N/A | J5: =VLOOKUP(E5,WTI!A5:B10527,2,0) -> 24.53 | K5: =VLOOKUP(F5,WTI!A5:B10527,2,0) -> 24.92 | L5: =IFERROR(LN(H5/G5),IFERROR(LN(I5/G5),IFERROR(LN(J5/G5),IFERROR(LN(K5/G5),"")))) -> 0.042470996
A6: 37377 | B6: 37393 | C6: =IF(B6="","",B6+1) -> 37394 | D6: =IF(B6="","",B6+2) -> 37395 | E6: =IF(B6="","",B6+3) -> 37396 | F6: =IF(B6="","",B6+4) -> 37397 | G6: =VLOOKUP(B6,WTI!A6:B10528,2,0) -> 28.19 | H6: =VLOOKUP(C6,WTI!A6:B10528,2,0) -> #N/A | I6: =VLOOKUP(D6,WTI!A6:B10528,2,0) -> #N/A | J6: =VLOOKUP(E6,WTI!A6:B10528,2,0) -> 28.24 | K6: =VLOOKUP(F6,WTI!A6:B10528,2,0) -> 27.35 | L6: =IFERROR(LN(H6/G6),IFERROR(LN(I6/G6),IFERROR(LN(J6/G6),IFERROR(LN(K6/G6),"")))) -> 0.0017721075
A7: 37408 | C7: =IF(B7="","",B7+1) | D7: =IF(B7="","",B7+2) | E7: =IF(B7="","",B7+3) | F7: =IF(B7="","",B7+4) | G7: =VLOOKUP(B7,WTI!A7:B10529,2,0) -> #N/A | H7: =VLOOKUP(C7,WTI!A7:B10529,2,0) -> #N/A | I7: =VLOOKUP(D7,WTI!A7:B10529,2,0) -> #N/A | J7: =VLOOKUP(E7,WTI!A7:B10529,2,0) -> #N/A | K7: =VLOOKUP(F7,WTI!A7:B10529,2,0) -> #N/A | L7: =IFERROR(LN(H7/G7),IFERROR(LN(I7/G7),IFERROR(LN(J7/G7),IFERROR(LN(K7/G7),""))))
A8: 37438 | B8: 37456 | C8: =IF(B8="","",B8+1) -> 37457 | D8: =IF(B8="","",B8+2) -> 37458 | E8: =IF(B8="","",B8+3) -> 37459 | F8: =IF(B8="","",B8+4) -> 37460 | G8: =VLOOKUP(B8,WTI!A8:B10530,2,0) -> 27.83 | H8: =VLOOKUP(C8,WTI!A8:B10530,2,0) -> #N/A | I8: =VLOOKUP(D8,WTI!A8:B10530,2,0) -> #N/A | J8: =VLOOKUP(E8,WTI!A8:B10530,2,0) -> 26.61 | K8: =VLOOKUP(F8,WTI!A8:B10530,2,0) -> 26.61 | L8: =IFERROR(LN(H8/G8),IFERROR(LN(I8/G8),IFERROR(LN(J8/G8),IFERROR(LN(K8/G8),"")))) -> -0.044827491
A9: 37469 | B9: 37484 | C9: =IF(B9="","",B9+1) -> 37485 | D9: =IF(B9="","",B9+2) -> 37486 | E9: =IF(B9="","",B9+3) -> 37487 | F9: =IF(B9="","",B9+4) -> 37488 | G9: =VLOOKUP(B9,WTI!A9:B10531,2,0) -> 29.24 | H9: =VLOOKUP(C9,WTI!A9:B10531,2,0) -> #N/A | I9: =VLOOKUP(D9,WTI!A9:B10531,2,0) -> #N/A | J9: =VLOOKUP(E9,WTI!A9:B10531,2,0) -> 29.86 | K9: =VLOOKUP(F9,WTI!A9:B10531,2,0) -> 30.12 | L9: =IFERROR(LN(H9/G9),IFERROR(LN(I9/G9),IFERROR(LN(J9/G9),IFERROR(LN(K9/G9),"")))) -> 0.020982157
A10: 37500 | B10: 37512 | C10: =IF(B10="","",B10+1) -> 37513 | D10: =IF(B10="","",B10+2) -> 37514 | E10: =IF(B10="","",B10+3) -> 37515 | F10: =IF(B10="","",B10+4) -> 37516 | G10: =VLOOKUP(B10,WTI!A10:B10532,2,0) -> 29.83 | H10: =VLOOKUP(C10,WTI!A10:B10532,2,0) -> #N/A | I10: =VLOOKUP(D10,WTI!A10:B10532,2,0) -> #N/A | J10: =VLOOKUP(E10,WTI!A10:B10532,2,0) -> 29.14 | K10: =VLOOKUP(F10,WTI!A10:B10532,2,0) -> 29.08 | L10: =IFERROR(LN(H10/G10),IFERROR(LN(I10/G10),IFERROR(LN(J10/G10),IFERROR(LN(K10/G10),"")))) -> -0.023402798
A11: 37530 | B11: 37547 | C11: =IF(B11="","",B11+1) -> 37548 | D11: =IF(B11="","",B11+2) -> 37549 | E11: =IF(B11="","",B11+3) -> 37550 | F11: =IF(B11="","",B11+4) -> 37551 | G11: =VLOOKUP(B11,WTI!A11:B10533,2,0) -> 29.56 | H11: =VLOOKUP(C11,WTI!A11:B10533,2,0) -> #N/A | I11: =VLOOKUP(D11,WTI!A11:B10533,2,0) -> #N/A | J11: =VLOOKUP(E11,WTI!A11:B10533,2,0) -> 28.31 | K11: =VLOOKUP(F11,WTI!A11:B10533,2,0) -> 27.93 | L11: =IFERROR(LN(H11/G11),IFERROR(LN(I11/G11),IFERROR(LN(J11/G11),IFERROR(LN(K11/G11),"")))) -> -0.043206997
A12: 37561 | B12: 37581 | C12: =IF(B12="","",B12+1) -> 37582 | D12: =IF(B12="","",B12+2) -> 37583 | E12: =IF(B12="","",B12+3) -> 37584 | F12: =IF(B12="","",B12+4) -> 37585 | G12: =VLOOKUP(B12,WTI!A12:B10534,2,0) -> 27.07 | H12: =VLOOKUP(C12,WTI!A12:B10534,2,0) -> 27.73 | I12: =VLOOKUP(D12,WTI!A12:B10534,2,0) -> #N/A | J12: =VLOOKUP(E12,WTI!A12:B10534,2,0) -> #N/A | K12: =VLOOKUP(F12,WTI!A12:B10534,2,0) -> 27.01 | L12: =IFERROR(LN(H12/G12),IFERROR(LN(I12/G12),IFERROR(LN(J12/G12),IFERROR(LN(K12/G12),"")))) -> 0.024088756
A13: 37591 | B13: 37613 | C13: =IF(B13="","",B13+1) -> 37614 | D13: =IF(B13="","",B13+2) -> 37615 | E13: =IF(B13="","",B13+3) -> 37616 | F13: =IF(B13="","",B13+4) -> 37617 | G13: =VLOOKUP(B13,WTI!A13:B10535,2,0) -> 32.09 | H13: =VLOOKUP(C13,WTI!A13:B10535,2,0) -> 32.13 | I13: =VLOOKUP(D13,WTI!A13:B10535,2,0) -> 32.13 | J13: =VLOOKUP(E13,WTI!A13:B10535,2,0) -> 32.61 | K13: =VLOOKUP(F13,WTI!A13:B10535,2,0) -> 32.68 | L13: =IFERROR(LN(H13/G13),IFERROR(LN(I13/G13),IFERROR(LN(J13/G13),IFERROR(LN(K13/G13),"")))) -> 0.001245718
A14: 37622 | C14: =IF(B14="","",B14+1) | D14: =IF(B14="","",B14+2) | E14: =IF(B14="","",B14+3) | F14: =IF(B14="","",B14+4) | G14: =VLOOKUP(B14,WTI!A14:B10536,2,0) -> #N/A | H14: =VLOOKUP(C14,WTI!A14:B10536,2,0) -> #N/A | I14: =VLOOKUP(D14,WTI!A14:B10536,2,0) -> #N/A | J14: =VLOOKUP(E14,WTI!A14:B10536,2,0) -> #N/A | K14: =VLOOKUP(F14,WTI!A14:B10536,2,0) -> #N/A | L14: =IFERROR(LN(H14/G14),IFERROR(LN(I14/G14),IFERROR(LN(J14/G14),IFERROR(LN(K14/G14),""))))
A15: 37653 | B15: 37666 | C15: =IF(B15="","",B15+1) -> 37667 | D15: =IF(B15="","",B15+2) -> 37668 | E15: =IF(B15="","",B15+3) -> 37669 | F15: =IF(B15="","",B15+4) -> 37670 | G15: =VLOOKUP(B15,WTI!A15:B10537,2,0) -> 36.61 | H15: =VLOOKUP(C15,WTI!A15:B10537,2,0) -> #N/A | I15: =VLOOKUP(D15,WTI!A15:B10537,2,0) -> #N/A | J15: =VLOOKUP(E15,WTI!A15:B10537,2,0) -> 36.61 | K15: =VLOOKUP(F15,WTI!A15:B10537,2,0) -> 36.88 | L15: =IFERROR(LN(H15/G15),IFERROR(LN(I15/G15),IFERROR(LN(J15/G15),IFERROR(LN(K15/G15),"")))) -> 0 | N15: -0.24 | P15: =IF(L15="",0,L15) -> 0 | R15: =IF(N15="",0,N15) -> -0.24
A16: 37681 | B16: 37694 | C16: =IF(B16="","",B16+1) -> 37695 | D16: =IF(B16="","",B16+2) -> 37696 | E16: =IF(B16="","",B16+3) -> 37697 | F16: =IF(B16="","",B16+4) -> 37698 | G16: =VLOOKUP(B16,WTI!A16:B10538,2,0) -> 35.41 | H16: =VLOOKUP(C16,WTI!A16:B10538,2,0) -> #N/A | I16: =VLOOKUP(D16,WTI!A16:B10538,2,0) -> #N/A | J16: =VLOOKUP(E16,WTI!A16:B10538,2,0) -> 34.92 | K16: =VLOOKUP(F16,WTI!A16:B10538,2,0) -> 31.55 | L16: =IFERROR(LN(H16/G16),IFERROR(LN(I16/G16),IFERROR(LN(J16/G16),IFERROR(LN(K16/G16),"")))) -> -0.013934535 | N16: -0.55 | P16: =IF(L16="",0,L16) -> -0.013934535 | R16: =IF(N16="",0,N16) -> -0.55
A17: 37712 | B17: 37739 | C17: =IF(B17="","",B17+1) -> 37740 | D17: =IF(B17="","",B17+2) -> 37741 | E17: =IF(B17="","",B17+3) -> 37742 | F17: =IF(B17="","",B17+4) -> 37743 | G17: =VLOOKUP(B17,WTI!A17:B10539,2,0) -> 25.25 | H17: =VLOOKUP(C17,WTI!A17:B10539,2,0) -> 25.32 | I17: =VLOOKUP(D17,WTI!A17:B10539,2,0) -> 26.09 | J17: =VLOOKUP(E17,WTI!A17:B10539,2,0) -> 26.05 | K17: =VLOOKUP(F17,WTI!A17:B10539,2,0) -> 25.74 | L17: =IFERROR(LN(H17/G17),IFERROR(LN(I17/G17),IFERROR(LN(J17/G17),IFERROR(LN(K17/G17),"")))) -> 0.0027684416 | N17: 0.16 | P17: =IF(L17="",0,L17) -> 0.0027684416 | R17: =IF(N17="",0,N17) -> 0.16
A18: 37742 | B18: 37757 | C18: =IF(B18="","",B18+1) -> 37758 | D18: =IF(B18="","",B18+2) -> 37759 | E18: =IF(B18="","",B18+3) -> 37760 | F18: =IF(B18="","",B18+4) -> 37761 | G18: =VLOOKUP(B18,WTI!A18:B10540,2,0) -> 29.07 | H18: =VLOOKUP(C18,WTI!A18:B10540,2,0) -> #N/A | I18: =VLOOKUP(D18,WTI!A18:B10540,2,0) -> #N/A | J18: =VLOOKUP(E18,WTI!A18:B10540,2,0) -> 28.84 | K18: =VLOOKUP(F18,WTI!A18:B10540,2,0) -> 29.29 | L18: =IFERROR(LN(H18/G18),IFERROR(LN(I18/G18),IFERROR(LN(J18/G18),IFERROR(LN(K18/G18),"")))) -> -0.0079434022 | N18: -1.03 | P18: =IF(L18="",0,L18) -> -0.0079434022 | R18: =IF(N18="",0,N18) -> -1.03
A19: 37773 | B19: 37792 | C19: =IF(B19="","",B19+1) -> 37793 | D19: =IF(B19="","",B19+2) -> 37794 | E19: =IF(B19="","",B19+3) -> 37795 | F19: =IF(B19="","",B19+4) -> 37796 | G19: =VLOOKUP(B19,WTI!A19:B10541,2,0) -> 30.63 | H19: =VLOOKUP(C19,WTI!A19:B10541,2,0) -> #N/A | I19: =VLOOKUP(D19,WTI!A19:B10541,2,0) -> #N/A | J19: =VLOOKUP(E19,WTI!A19:B10541,2,0) -> 30.22 | K19: =VLOOKUP(F19,WTI!A19:B10541,2,0) -> 30.05 | L19: =IFERROR(LN(H19/G19),IFERROR(LN(I19/G19),IFERROR(LN(J19/G19),IFERROR(LN(K19/G19),"")))) -> -0.013475964 | N19: 0.32 | P19: =IF(L19="",0,L19) -> -0.013475964 | R19: =IF(N19="",0,N19) -> 0.32
A20: 37803 | B20: 37827 | C20: =IF(B20="","",B20+1) -> 37828 | D20: =IF(B20="","",B20+2) -> 37829 | E20: =IF(B20="","",B20+3) -> 37830 | F20: =IF(B20="","",B20+4) -> 37831 | G20: =VLOOKUP(B20,WTI!A20:B10542,2,0) -> 30.31 | H20: =VLOOKUP(C20,WTI!A20:B10542,2,0) -> #N/A | I20: =VLOOKUP(D20,WTI!A20:B10542,2,0) -> #N/A | J20: =VLOOKUP(E20,WTI!A20:B10542,2,0) -> 29.98 | K20: =VLOOKUP(F20,WTI!A20:B10542,2,0) -> 30.21 | L20: =IFERROR(LN(H20/G20),IFERROR(LN(I20/G20),IFERROR(LN(J20/G20),IFERROR(LN(K20/G20),"")))) -> -0.010947198 | N20: 0.19 | P20: =IF(L20="",0,L20) -> -0.010947198 | R20: =IF(N20="",0,N20) -> 0.19
A21: 37834 | B21: 37848 | C21: =IF(B21="","",B21+1) -> 37849 | D21: =IF(B21="","",B21+2) -> 37850 | E21: =IF(B21="","",B21+3) -> 37851 | F21: =IF(B21="","",B21+4) -> 37852 | G21: =VLOOKUP(B21,WTI!A21:B10543,2,0) -> 31.01 | H21: =VLOOKUP(C21,WTI!A21:B10543,2,0) -> #N/A | I21: =VLOOKUP(D21,WTI!A21:B10543,2,0) -> #N/A | J21: =VLOOKUP(E21,WTI!A21:B10543,2,0) -> 30.81 | K21: =VLOOKUP(F21,WTI!A21:B10543,2,0) -> 30.76 | L21: =IFERROR(LN(H21/G21),IFERROR(LN(I21/G21),IFERROR(LN(J21/G21),IFERROR(LN(K21/G21),"")))) -> -0.0064704205 | N21: -0.03 | P21: =IF(L21="",0,L21) -> -0.0064704205 | R21: =IF(N21="",0,N21) -> -0.03
A22: 37865 | B22: 37876 | C22: =IF(B22="","",B22+1) -> 37877 | D22: =IF(B22="","",B22+2) -> 37878 | E22: =IF(B22="","",B22+3) -> 37879 | F22: =IF(B22="","",B22+4) -> 37880 | G22: =VLOOKUP(B22,WTI!A22:B10544,2,0) -> 28.26 | H22: =VLOOKUP(C22,WTI!A22:B10544,2,0) -> #N/A | I22: =VLOOKUP(D22,WTI!A22:B10544,2,0) -> #N/A | J22: =VLOOKUP(E22,WTI!A22:B10544,2,0) -> 28.15 | K22: =VLOOKUP(F22,WTI!A22:B10544,2,0) -> 27.6 | L22: =IFERROR(LN(H22/G22),IFERROR(LN(I22/G22),IFERROR(LN(J22/G22),IFERROR(LN(K22/G22),"")))) -> -0.0039000227 | N22: -0.03 | P22: =IF(L22="",0,L22) -> -0.0039000227 | R22: =IF(N22="",0,N22) -> -0.03
A23: 37895 | B23: 37918 | C23: =IF(B23="","",B23+1) -> 37919 | D23: =IF(B23="","",B23+2) -> 37920 | E23: =IF(B23="","",B23+3) -> 37921 | F23: =IF(B23="","",B23+4) -> 37922 | G23: =VLOOKUP(B23,WTI!A23:B10545,2,0) -> 29.99 | H23: =VLOOKUP(C23,WTI!A23:B10545,2,0) -> #N/A | I23: =VLOOKUP(D23,WTI!A23:B10545,2,0) -> #N/A | J23: =VLOOKUP(E23,WTI!A23:B10545,2,0) -> 29.95 | K23: =VLOOKUP(F23,WTI!A23:B10545,2,0) -> 29.57 | L23: =IFERROR(LN(H23/G23),IFERROR(LN(I23/G23),IFERROR(LN(J23/G23),IFERROR(LN(K23/G23),"")))) -> -0.0013346682 | N23: -0.14 | P23: =IF(L23="",0,L23) -> -0.0013346682 | R23: =IF(N23="",0,N23) -> -0.14
A24: 37926 | B24: 37939 | C24: =IF(B24="","",B24+1) -> 37940 | D24: =IF(B24="","",B24+2) -> 37941 | E24: =IF(B24="","",B24+3) -> 37942 | F24: =IF(B24="","",B24+4) -> 37943 | G24: =VLOOKUP(B24,WTI!A24:B10546,2,0) -> 32.31 | H24: =VLOOKUP(C24,WTI!A24:B10546,2,0) -> #N/A | I24: =VLOOKUP(D24,WTI!A24:B10546,2,0) -> #N/A | J24: =VLOOKUP(E24,WTI!A24:B10546,2,0) -> 31.75 | K24: =VLOOKUP(F24,WTI!A24:B10546,2,0) -> 33.16 | L24: =IFERROR(LN(H24/G24),IFERROR(LN(I24/G24),IFERROR(LN(J24/G24),IFERROR(LN(K24/G24),"")))) -> -0.017484054 | N24: 0.49 | P24: =IF(L24="",0,L24) -> -0.017484054 | R24: =IF(N24="",0,N24) -> 0.49
A25: 37956 | B25: 37974 | C25: =IF(B25="","",B25+1) -> 37975 | D25: =IF(B25="","",B25+2) -> 37976 | E25: =IF(B25="","",B25+3) -> 37977 | F25: =IF(B25="","",B25+4) -> 37978 | G25: =VLOOKUP(B25,WTI!A25:B10547,2,0) -> 32.81 | H25: =VLOOKUP(C25,WTI!A25:B10547,2,0) -> #N/A | I25: =VLOOKUP(D25,WTI!A25:B10547,2,0) -> #N/A | J25: =VLOOKUP(E25,WTI!A25:B10547,2,0) -> 31.71 | K25: =VLOOKUP(F25,WTI!A25:B10547,2,0) -> 32.03 | L25: =IFERROR(LN(H25/G25),IFERROR(LN(I25/G25),IFERROR(LN(J25/G25),IFERROR(LN(K25/G25),"")))) -> -0.034101258 | N25: 0.18 | P25: =IF(L25="",0,L25) -> -0.034101258 | R25: =IF(N25="",0,N25) -> 0.18
A26: 37987 | B26: 38009 | C26: =IF(B26="","",B26+1) -> 38010 | D26: =IF(B26="","",B26+2) -> 38011 | E26: =IF(B26="","",B26+3) -> 38012 | F26: =IF(B26="","",B26+4) -> 38013 | G26: =VLOOKUP(B26,WTI!A26:B10548,2,0) -> 34.94 | H26: =VLOOKUP(C26,WTI!A26:B10548,2,0) -> #N/A | I26: =VLOOKUP(D26,WTI!A26:B10548,2,0) -> #N/A | J26: =VLOOKUP(E26,WTI!A26:B10548,2,0) -> 34.41 | K26: =VLOOKUP(F26,WTI!A26:B10548,2,0) -> 33.99 | L26: =IFERROR(LN(H26/G26),IFERROR(LN(I26/G26),IFERROR(LN(J26/G26),IFERROR(LN(K26/G26),"")))) -> -0.015285085 | N26: -0.09 | P26: =IF(L26="",0,L26) -> -0.015285085 | R26: =IF(N26="",0,N26) -> -0.09
... A77: 39539 | B77: 39563 | C77: =IF(B77="","",B77+1) -> 39564 | D77: =IF(B77="","",B77+2) -> 39565 | E77: =IF(B77="","",B77+3) -> 39566 | F77: =IF(B77="","",B77+4) -> 39567 | G77: =VLOOKUP(B77,WTI!A77:B10599,2,0) -> 119.64 | H77: =VLOOKUP(C77,WTI!A77:B10599,2,0) -> #N/A | I77: =VLOOKUP(D77,WTI!A77:B10599,2,0) -> #N/A | J77: =VLOOKUP(E77,WTI!A77:B10599,2,0) -> 118.78 | K77: =VLOOKUP(F77,WTI!A77:B10599,2,0) -> 115.67 | L77: =IFERROR(LN(H77/G77),IFERROR(LN(I77/G77),IFERROR(LN(J77/G77),IFERROR(LN(K77/G77),"")))) -> -0.0072141912 | N77: 5.53 | P77: =IF(L77="",0,L77) -> -0.0072141912 | R77: =IF(N77="",0,N77) -> 5.53
A78: 39569 | B78: 39591 | C78: =IF(B78="","",B78+1) -> 39592 | D78: =IF(B78="","",B78+2) -> 39593 | E78: =IF(B78="","",B78+3) -> 39594 | F78: =IF(B78="","",B78+4) -> 39595 | G78: =VLOOKUP(B78,WTI!A78:B10600,2,0) -> 131.58 | H78: =VLOOKUP(C78,WTI!A78:B10600,2,0) -> #N/A | I78: =VLOOKUP(D78,WTI!A78:B10600,2,0) -> #N/A | J78: =VLOOKUP(E78,WTI!A78:B10600,2,0) -> 131.58 | K78: =VLOOKUP(F78,WTI!A78:B10600,2,0) -> 128.81 | L78: =IFERROR(LN(H78/G78),IFERROR(LN(I78/G78),IFERROR(LN(J78/G78),IFERROR(LN(K78/G78),"")))) -> 0 | M78: -0.0035654222 | N78: -5.53 | P78: =IF(L78="",0,L78) -> 0 | Q78: =IF(M78="",0,M78) -> -0.0035654222 | R78: =IF(N78="",0,N78) -> -5.53
A79: 39600 | B79: 39619 | C79: =IF(B79="","",B79+1) -> 39620 | D79: =IF(B79="","",B79+2) -> 39621 | E79: =IF(B79="","",B79+3) -> 39622 | F79: =IF(B79="","",B79+4) -> 39623 | G79: =VLOOKUP(B79,WTI!A79:B10601,2,0) -> 134.78 | H79: =VLOOKUP(C79,WTI!A79:B10601,2,0) -> #N/A | I79: =VLOOKUP(D79,WTI!A79:B10601,2,0) -> #N/A | J79: =VLOOKUP(E79,WTI!A79:B10601,2,0) -> 135.98 | K79: =VLOOKUP(F79,WTI!A79:B10601,2,0) -> 136.49 | L79: =IFERROR(LN(H79/G79),IFERROR(LN(I79/G79),IFERROR(LN(J79/G79),IFERROR(LN(K79/G79),"")))) -> 0.0088639966 | M79: -0.00014595496 | N79: -5.45 | P79: =IF(L79="",0,L79) -> 0.0088639966 | Q79: =IF(M79="",0,M79) -> -0.00014595496 | R79: =IF(N79="",0,N79) -> -5.45
A80: 39630 | B80: 39654 | C80: =IF(B80="","",B80+1) -> 39655 | D80: =IF(B80="","",B80+2) -> 39656 | E80: =IF(B80="","",B80+3) -> 39657 | F80: =IF(B80="","",B80+4) -> 39658 | G80: =VLOOKUP(B80,WTI!A80:B10602,2,0) -> 122.59 | H80: =VLOOKUP(C80,WTI!A80:B10602,2,0) -> #N/A | I80: =VLOOKUP(D80,WTI!A80:B10602,2,0) -> #N/A | J80: =VLOOKUP(E80,WTI!A80:B10602,2,0) -> 124.72 | K80: =VLOOKUP(F80,WTI!A80:B10602,2,0) -> 122.21 | L80: =IFERROR(LN(H80/G80),IFERROR(LN(I80/G80),IFERROR(LN(J80/G80),IFERROR(LN(K80/G80),"")))) -> 0.017225771 | M80: -0.011485516 | N80: 5.12 | P80: =IF(L80="",0,L80) -> 0.017225771 | Q80: =IF(M80="",0,M80) -> -0.011485516 | R80: =IF(N80="",0,N80) -> 5.12
A81: 39661 | B81: 39675 | C81: =IF(B81="","",B81+1) -> 39676 | D81: =IF(B81="","",B81+2) -> 39677 | E81: =IF(B81="","",B81+3) -> 39678 | F81: =IF(B81="","",B81+4) -> 39679 | G81: =VLOOKUP(B81,WTI!A81:B10603,2,0) -> 113.46 | H81: =VLOOKUP(C81,WTI!A81:B10603,2,0) -> #N/A | I81: =VLOOKUP(D81,WTI!A81:B10603,2,0) -> #N/A | J81: =VLOOKUP(E81,WTI!A81:B10603,2,0) -> 112.92 | K81: =VLOOKUP(F81,WTI!A81:B10603,2,0) -> 114.39 | L81: =IFERROR(LN(H81/G81),IFERROR(LN(I81/G81),IFERROR(LN(J81/G81),IFERROR(LN(K81/G81),"")))) -> -0.0047707485 | M81: -0.0041147084 | N81: -0.06 | P81: =IF(L81="",0,L81) -> -0.0047707485 | Q81: =IF(M81="",0,M81) -> -0.0041147084 | R81: =IF(N81="",0,N81) -> -0.06
A82: 39692 | B82: 39710 | C82: =IF(B82="","",B82+1) -> 39711 | D82: =IF(B82="","",B82+2) -> 39712 | E82: =IF(B82="","",B82+3) -> 39713 | F82: =IF(B82="","",B82+4) -> 39714 | G82: =VLOOKUP(B82,WTI!A82:B10604,2,0) -> 104.05 | H82: =VLOOKUP(C82,WTI!A82:B10604,2,0) -> #N/A | I82: =VLOOKUP(D82,WTI!A82:B10604,2,0) -> #N/A | J82: =VLOOKUP(E82,WTI!A82:B10604,2,0) -> 122.61 | K82: =VLOOKUP(F82,WTI!A82:B10604,2,0) -> 107.85 | L82: =IFERROR(LN(H82/G82),IFERROR(LN(I82/G82),IFERROR(LN(J82/G82),IFERROR(LN(K82/G82),"")))) -> 0.16413703 | M82: -0.0020831965 | N82: 0.39 | P82: =IF(L82="",0,L82) -> 0.16413703 | Q82: =IF(M82="",0,M82) -> -0.0020831965 | R82: =IF(N82="",0,N82) -> 0.39
A83: 39722 | B83: 39745 | C83: =IF(B83="","",B83+1) -> 39746 | D83: =IF(B83="","",B83+2) -> 39747 | E83: =IF(B83="","",B83+3) -> 39748 | F83: =IF(B83="","",B83+4) -> 39749 | G83: =VLOOKUP(B83,WTI!A83:B10605,2,0) -> 63.34 | H83: =VLOOKUP(C83,WTI!A83:B10605,2,0) -> #N/A | I83: =VLOOKUP(D83,WTI!A83:B10605,2,0) -> #N/A | J83: =VLOOKUP(E83,WTI!A83:B10605,2,0) -> 61.92 | K83: =VLOOKUP(F83,WTI!A83:B10605,2,0) -> 62.8 | L83: =IFERROR(LN(H83/G83),IFERROR(LN(I83/G83),IFERROR(LN(J83/G83),IFERROR(LN(K83/G83),"")))) -> -0.022673812 | M83: -0.028611729 | N83: -6.16 | P83: =IF(L83="",0,L83) -> -0.022673812 | Q83: =IF(M83="",0,M83) -> -0.028611729 | R83: =IF(N83="",0,N83) -> -6.16
